Workbook

Sheet INPUT DATA
A1: Input Data Sheet for Electronic-Class Record (ECR)
B7: SCHOOL INFORMATION | I7: LEARNERS' NAMES
C10: REGION | D10: : | J10: MALE | M10: FEMALE
C11: DIVISION | D11: : | J11: 1 | M11: 1
J12: 2 | M12: 2
C13: SCHOOL ID | D13: : | J13: 3 | M13: 3
C14: SCHOOL NAME | D14: : | J14: 4 | M14: 4
C15: SCHOOL YEAR | D15: : | J15: 5 | M15: 5
C16: SCHOOL HEAD | D16: : | J16: 6 | M16: 6
J17: 7 | M17: 7
J18: 8 | M18: 8
J19: 9 | M19: 9
B20: TEACHER, GRADE LEVEL, SECTION INFORMATION | J20: 10 | M20: 10
J21: 11 | M21: 11
J22: 12 | M22: 12
C23: SUBJECT TEACHER | D23: : | J23: 13 | M23: 13
C24: SUBJECT | D24: : | J24: 14 | M24: 14
C25: GRADE LEVEL | D25: : | J25: 15 | M25: 15
C26: SECTION | D26: : | J26: 16 | M26: 16
J27: 17 | M27: 17
C28: IMPORTANT NOTE: This is the official and final version of the file. All tabs are password-protected to prevent accidental formula edits and maintain the accuracy and integrity of the data. If you identify any inconsistencies or issues, particularly with the formulas, please report them for appropriate review and necessary correction. | J28: 18 | M28: 18
J29: 19 | M29: 19
J30: 20 | M30: 20
J31: 21 | M31: 21
J32: 22 | M32: 22
J33: 23 | M33: 23
J34: 24 | M34: 24
J35: 25 | M35: 25
B36: Sheet Protection Password: password123 | J36: 26 | M36: 26
J37: 27 | M37: 27
J38: 28 | M38: 28
J39: 29 | M39: 29
J40: 30 | M40: 30
J41: 31 | M41: 31
J42: 32 | M42: 32
J43: 33 | M43: 33
J44: 34 | M44: 34
J45: 35 | M45: 35
J46: 36 | M46: 36
J47: 37 | M47: 37
...

Sheet TERM 1
B2: CLASS RECORD
E5: REGION | F5: =IF('INPUT DATA'!E10="","",'INPUT DATA'!E10) | Q5: DIVISION | R5: =IF('INPUT DATA'!E11="","",'INPUT DATA'!E11) | Y5: SCHOOL ID | Z5: =IF('INPUT DATA'!E13="","",'INPUT DATA'!E13)
E7: SCHOOL NAME | F7: =IF('INPUT DATA'!E14="","",'INPUT DATA'!E14) | Y7: SCHOOL YEAR | Z7: =IF('INPUT DATA'!E15="","",'INPUT DATA'!E15)
B10: FIRST TERM | F10: GRADE LEVEL | J10: =IF('INPUT DATA'!E25="","",'INPUT DATA'!E25) | N10: TEACHER | Q10: =IF('INPUT DATA'!E23="","",'INPUT DATA'!E23) | Y10: SUBJECT | AA10: =IF('INPUT DATA'!E24="","",'INPUT DATA'!E24)
F11: SECTION | J11: =IF('INPUT DATA'!E26="","",'INPUT DATA'!E26)
F12: WRITTEN / ORAL WORKS (WWs) | N12: PRODUCT / PERFORMANCE TASKS (PTs) | T12: EXAMINATIONS (EXs) | AB12: Initial Grade | AC12: Term Grade | AD12: Descriptor
F14: 1 | G14: 2 | H14: 3 | I14: 4 | J14: 5 | K14: Total | L14: PS | M14: WS | N14: 1 | O14: 2 | P14: 3 | Q14: Total | R14: PS | S14: WS | T14: ST1 | U14: ST2 | V14: TE | W14: WS ST1 | X14: WS ST2 | Y14: WS TE | Z14: PS | AA14: WS
B15: HIGHEST POSSIBLE SCORE | K15: =IF(COUNT(F15:J15)=0,"",SUM(F15:J15)) | L15: 100 | M15: 0.2 | Q15: =IF(COUNT(N15:P15)=0,"",SUM(N15:P15)) | R15: 100 | S15: 0.6 | W15: 30 | X15: 30 | Y15: 40 | Z15: 100 | AA15: 0.2
B16: LEARNERS' NAMES
B17: MALE
B18: 1 | C18: =IF('INPUT DATA'!K11="","",'INPUT DATA'!K11) | K18: =IF(COUNT($F18:$J18)=0,"",SUM($F18:$J18)) | L18: =IF(COUNT(F18:J18)=0,"",IFERROR(K18/$K$15*$L$15,"")) | M18: =IF(L18="","",L18*$M$15) | Q18: =IF(COUNT(N18:P18)=0,"",SUM(N18:P18)) | R18: =IF(COUNT(N18:P18)=0,"",IFERROR(Q18/$Q$15*$R$15,"")) | S18: =IF(R18="","",R18*$S$15) | W18: =IF(T18="","",IFERROR(T18/$T$15*$W$15,"")) | X18: =IF(U18="","",IFERROR(U18/$U$15*$X$15,"")) | Y18: =IF(V18="","",IFERROR(V18/$V$15*$Y$15,"")) | Z18: =IF(COUNT(T18:V18)=0,"",SUM(W18:Y18)) | AA18: =IF(Z18="","",Z18*$AA$15) | AB18: =IF(COUNT(F18:J18,N18:P18,T18:V18)=0,"",SUM(M18,S18,AA18)) | AC18: =IF(AB18="","",IFERROR(INDEX(HELPER!$D$8:$D$48,IF(AB18>=HELPER!$B$8,1,MATCH(AB18,HELPER!$B$8:$B$48,-1)+1)),"")) | AD18: =IF(AC18="","",IFERROR(INDEX(HELPER!$G$8:$G$48,MATCH(AC18,HELPER!$F$8:$F$48,-1)),""))
B19: 2 | C19: =IF('INPUT DATA'!K12="","",'INPUT DATA'!K12) | K19: =IF(COUNT($F19:$J19)=0,"",SUM($F19:$J19)) | L19: =IF(COUNT(F19:J19)=0,"",IFERROR(K19/$K$15*$L$15,"")) | M19: =IF(L19="","",L19*$M$15) | Q19: =IF(COUNT(N19:P19)=0,"",SUM(N19:P19)) | R19: =IF(COUNT(N19:P19)=0,"",IFERROR(Q19/$Q$15*$R$15,"")) | S19: =IF(R19="","",R19*$S$15) | W19: =IF(T19="","",IFERROR(T19/$T$15*$W$15,"")) | X19: =IF(U19="","",IFERROR(U19/$U$15*$X$15,"")) | Y19: =IF(V19="","",IFERROR(V19/$V$15*$Y$15,"")) | Z19: =IF(COUNT(T19:V19)=0,"",SUM(W19:Y19)) | AA19: =IF(Z19="","",Z19*$AA$15) | AB19: =IF(COUNT(F19:J19,N19:P19,T19:V19)=0,"",SUM(M19,S19,AA19)) | AC19: =IF(AB19="","",IFERROR(INDEX(HELPER!$D$8:$D$48,IF(AB19>=HELPER!$B$8,1,MATCH(AB19,HELPER!$B$8:$B$48,-1)+1)),"")) | AD19: =IF(AC19="","",IFERROR(INDEX(HELPER!$G$8:$G$48,MATCH(AC19,HELPER!$F$8:$F$48,-1)),""))
B20: 3 | C20: =IF('INPUT DATA'!K13="","",'INPUT DATA'!K13) | K20: =IF(COUNT($F20:$J20)=0,"",SUM($F20:$J20)) | L20: =IF(COUNT(F20:J20)=0,"",IFERROR(K20/$K$15*$L$15,"")) | M20: =IF(L20="","",L20*$M$15) | Q20: =IF(COUNT(N20:P20)=0,"",SUM(N20:P20)) | R20: =IF(COUNT(N20:P20)=0,"",IFERROR(Q20/$Q$15*$R$15,"")) | S20: =IF(R20="","",R20*$S$15) | W20: =IF(T20="","",IFERROR(T20/$T$15*$W$15,"")) | X20: =IF(U20="","",IFERROR(U20/$U$15*$X$15,"")) | Y20: =IF(V20="","",IFERROR(V20/$V$15*$Y$15,"")) | Z20: =IF(COUNT(T20:V20)=0,"",SUM(W20:Y20)) | AA20: =IF(Z20="","",Z20*$AA$15) | AB20: =IF(COUNT(F20:J20,N20:P20,T20:V20)=0,"",SUM(M20,S20,AA20)) | AC20: =IF(AB20="","",IFERROR(INDEX(HELPER!$D$8:$D$48,IF(AB20>=HELPER!$B$8,1,MATCH(AB20,HELPER!$B$8:$B$48,-1)+1)),"")) | AD20: =IF(AC20="","",IFERROR(INDEX(HELPER!$G$8:$G$48,MATCH(AC20,HELPER!$F$8:$F$48,-1)),""))
B21: 4 | C21: =IF('INPUT DATA'!K14="","",'INPUT DATA'!K14) | K21: =IF(COUNT($F21:$J21)=0,"",SUM($F21:$J21)) | L21: =IF(COUNT(F21:J21)=0,"",IFERROR(K21/$K$15*$L$15,"")) | M21: =IF(L21="","",L21*$M$15) | Q21: =IF(COUNT(N21:P21)=0,"",SUM(N21:P21)) | R21: =IF(COUNT(N21:P21)=0,"",IFERROR(Q21/$Q$15*$R$15,"")) | S21: =IF(R21="","",R21*$S$15) | W21: =IF(T21="","",IFERROR(T21/$T$15*$W$15,"")) | X21: =IF(U21="","",IFERROR(U21/$U$15*$X$15,"")) | Y21: =IF(V21="","",IFERROR(V21/$V$15*$Y$15,"")) | Z21: =IF(COUNT(T21:V21)=0,"",SUM(W21:Y21)) | AA21: =IF(Z21="","",Z21*$AA$15) | AB21: =IF(COUNT(F21:J21,N21:P21,T21:V21)=0,"",SUM(M21,S21,AA21)) | AC21: =IF(AB21="","",IFERROR(INDEX(HELPER!$D$8:$D$48,IF(AB21>=HELPER!$B$8,1,MATCH(AB21,HELPER!$B$8:$B$48,-1)+1)),"")) | AD21: =IF(AC21="","",IFERROR(INDEX(HELPER!$G$8:$G$48,MATCH(AC21,HELPER!$F$8:$F$48,-1)),""))
B22: 5 | C22: =IF('INPUT DATA'!K15="","",'INPUT DATA'!K15) | K22: =IF(COUNT($F22:$J22)=0,"",SUM($F22:$J22)) | L22: =IF(COUNT(F22:J22)=0,"",IFERROR(K22/$K$15*$L$15,"")) | M22: =IF(L22="","",L22*$M$15) | Q22: =IF(COUNT(N22:P22)=0,"",SUM(N22:P22)) | R22: =IF(COUNT(N22:P22)=0,"",IFERROR(Q22/$Q$15*$R$15,"")) | S22: =IF(R22="","",R22*$S$15) | W22: =IF(T22="","",IFERROR(T22/$T$15*$W$15,"")) | X22: =IF(U22="","",IFERROR(U22/$U$15*$X$15,"")) | Y22: =IF(V22="","",IFERROR(V22/$V$15*$Y$15,"")) | Z22: =IF(COUNT(T22:V22)=0,"",SUM(W22:Y22)) | AA22: =IF(Z22="","",Z22*$AA$15) | AB22: =IF(COUNT(F22:J22,N22:P22,T22:V22)=0,"",SUM(M22,S22,AA22)) | AC22: =IF(AB22="","",IFERROR(INDEX(HELPER!$D$8:$D$48,IF(AB22>=HELPER!$B$8,1,MATCH(AB22,HELPER!$B$8:$B$48,-1)+1)),"")) | AD22: =IF(AC22="","",IFERROR(INDEX(HELPER!$G$8:$G$48,MATCH(AC22,HELPER!$F$8:$F$48,-1)),""))
B23: 6 | C23: =IF('INPUT DATA'!K16="","",'INPUT DATA'!K16) | K23: =IF(COUNT($F23:$J23)=0,"",SUM($F23:$J23)) | L23: =IF(COUNT(F23:J23)=0,"",IFERROR(K23/$K$15*$L$15,"")) | M23: =IF(L23="","",L23*$M$15) | Q23: =IF(COUNT(N23:P23)=0,"",SUM(N23:P23)) | R23: =IF(COUNT(N23:P23)=0,"",IFERROR(Q23/$Q$15*$R$15,"")) | S23: =IF(R23="","",R23*$S$15) | W23: =IF(T23="","",IFERROR(T23/$T$15*$W$15,"")) | X23: =IF(U23="","",IFERROR(U23/$U$15*$X$15,"")) | Y23: =IF(V23="","",IFERROR(V23/$V$15*$Y$15,"")) | Z23: =IF(COUNT(T23:V23)=0,"",SUM(W23:Y23)) | AA23: =IF(Z23="","",Z23*$AA$15) | AB23: =IF(COUNT(F23:J23,N23:P23,T23:V23)=0,"",SUM(M23,S23,AA23)) | AC23: =IF(AB23="","",IFERROR(INDEX(HELPER!$D$8:$D$48,IF(AB23>=HELPER!$B$8,1,MATCH(AB23,HELPER!$B$8:$B$48,-1)+1)),"")) | AD23: =IF(AC23="","",IFERROR(INDEX(HELPER!$G$8:$G$48,MATCH(AC23,HELPER!$F$8:$F$48,-1)),""))
B24: 7 | C24: =IF('INPUT DATA'!K17="","",'INPUT DATA'!K17) | K24: =IF(COUNT($F24:$J24)=0,"",SUM($F24:$J24)) | L24: =IF(COUNT(F24:J24)=0,"",IFERROR(K24/$K$15*$L$15,"")) | M24: =IF(L24="","",L24*$M$15) | Q24: =IF(COUNT(N24:P24)=0,"",SUM(N24:P24)) | R24: =IF(COUNT(N24:P24)=0,"",IFERROR(Q24/$Q$15*$R$15,"")) | S24: =IF(R24="","",R24*$S$15) | W24: =IF(T24="","",IFERROR(T24/$T$15*$W$15,"")) | X24: =IF(U24="","",IFERROR(U24/$U$15*$X$15,"")) | Y24: =IF(V24="","",IFERROR(V24/$V$15*$Y$15,"")) | Z24: =IF(COUNT(T24:V24)=0,"",SUM(W24:Y24)) | AA24: =IF(Z24="","",Z24*$AA$15) | AB24: =IF(COUNT(F24:J24,N24:P24,T24:V24)=0,"",SUM(M24,S24,AA24)) | AC24: =IF(AB24="","",IFERROR(INDEX(HELPER!$D$8:$D$48,IF(AB24>=HELPER!$B$8,1,MATCH(AB24,HELPER!$B$8:$B$48,-1)+1)),"")) | AD24: =IF(AC24="","",IFERROR(INDEX(HELPER!$G$8:$G$48,MATCH(AC24,HELPER!$F$8:$F$48,-1)),""))
B25: 8 | C25: =IF('INPUT DATA'!K18="","",'INPUT DATA'!K18) | K25: =IF(COUNT($F25:$J25)=0,"",SUM($F25:$J25)) | L25: =IF(COUNT(F25:J25)=0,"",IFERROR(K25/$K$15*$L$15,"")) | M25: =IF(L25="","",L25*$M$15) | Q25: =IF(COUNT(N25:P25)=0,"",SUM(N25:P25)) | R25: =IF(COUNT(N25:P25)=0,"",IFERROR(Q25/$Q$15*$R$15,"")) | S25: =IF(R25="","",R25*$S$15) | W25: =IF(T25="","",IFERROR(T25/$T$15*$W$15,"")) | X25: =IF(U25="","",IFERROR(U25/$U$15*$X$15,"")) | Y25: =IF(V25="","",IFERROR(V25/$V$15*$Y$15,"")) | Z25: =IF(COUNT(T25:V25)=0,"",SUM(W25:Y25)) | AA25: =IF(Z25="","",Z25*$AA$15) | AB25: =IF(COUNT(F25:J25,N25:P25,T25:V25)=0,"",SUM(M25,S25,AA25)) | AC25: =IF(AB25="","",IFERROR(INDEX(HELPER!$D$8:$D$48,IF(AB25>=HELPER!$B$8,1,MATCH(AB25,HELPER!$B$8:$B$48,-1)+1)),"")) | AD25: =IF(AC25="","",IFERROR(INDEX(HELPER!$G$8:$G$48,MATCH(AC25,HELPER!$F$8:$F$48,-1)),""))
B26: 9 | C26: =IF('INPUT DATA'!K19="","",'INPUT DATA'!K19) | K26: =IF(COUNT($F26:$J26)=0,"",SUM($F26:$J26)) | L26: =IF(COUNT(F26:J26)=0,"",IFERROR(K26/$K$15*$L$15,"")) | M26: =IF(L26="","",L26*$M$15) | Q26: =IF(COUNT(N26:P26)=0,"",SUM(N26:P26)) | R26: =IF(COUNT(N26:P26)=0,"",IFERROR(Q26/$Q$15*$R$15,"")) | S26: =IF(R26="","",R26*$S$15) | W26: =IF(T26="","",IFERROR(T26/$T$15*$W$15,"")) | X26: =IF(U26="","",IFERROR(U26/$U$15*$X$15,"")) | Y26: =IF(V26="","",IFERROR(V26/$V$15*$Y$15,"")) | Z26: =IF(COUNT(T26:V26)=0,"",SUM(W26:Y26)) | AA26: =IF(Z26="","",Z26*$AA$15) | AB26: =IF(COUNT(F26:J26,N26:P26,T26:V26)=0,"",SUM(M26,S26,AA26)) | AC26: =IF(AB26="","",IFERROR(INDEX(HELPER!$D$8:$D$48,IF(AB26>=HELPER!$B$8,1,MATCH(AB26,HELPER!$B$8:$B$48,-1)+1)),"")) | AD26: =IF(AC26="","",IFERROR(INDEX(HELPER!$G$8:$G$48,MATCH(AC26,HELPER!$F$8:$F$48,-1)),""))
B27: 10 | C27: =IF('INPUT DATA'!K20="","",'INPUT DATA'!K20) | K27: =IF(COUNT($F27:$J27)=0,"",SUM($F27:$J27)) | L27: =IF(COUNT(F27:J27)=0,"",IFERROR(K27/$K$15*$L$15,"")) | M27: =IF(L27="","",L27*$M$15) | Q27: =IF(COUNT(N27:P27)=0,"",SUM(N27:P27)) | R27: =IF(COUNT(N27:P27)=0,"",IFERROR(Q27/$Q$15*$R$15,"")) | S27: =IF(R27="","",R27*$S$15) | W27: =IF(T27="","",IFERROR(T27/$T$15*$W$15,"")) | X27: =IF(U27="","",IFERROR(U27/$U$15*$X$15,"")) | Y27: =IF(V27="","",IFERROR(V27/$V$15*$Y$15,"")) | Z27: =IF(COUNT(T27:V27)=0,"",SUM(W27:Y27)) | AA27: =IF(Z27="","",Z27*$AA$15) | AB27: =IF(COUNT(F27:J27,N27:P27,T27:V27)=0,"",SUM(M27,S27,AA27)) | AC27: =IF(AB27="","",IFERROR(INDEX(HELPER!$D$8:$D$48,IF(AB27>=HELPER!$B$8,1,MATCH(AB27,HELPER!$B$8:$B$48,-1)+1)),"")) | AD27: =IF(AC27="","",IFERROR(INDEX(HELPER!$G$8:$G$48,MATCH(AC27,HELPER!$F$8:$F$48,-1)),""))
B28: 11 | C28: =IF('INPUT DATA'!K21="","",'INPUT DATA'!K21) | K28: =IF(COUNT($F28:$J28)=0,"",SUM($F28:$J28)) | L28: =IF(COUNT(F28:J28)=0,"",IFERROR(K28/$K$15*$L$15,"")) | M28: =IF(L28="","",L28*$M$15) | Q28: =IF(COUNT(N28:P28)=0,"",SUM(N28:P28)) | R28: =IF(COUNT(N28:P28)=0,"",IFERROR(Q28/$Q$15*$R$15,"")) | S28: =IF(R28="","",R28*$S$15) | W28: =IF(T28="","",IFERROR(T28/$T$15*$W$15,"")) | X28: =IF(U28="","",IFERROR(U28/$U$15*$X$15,"")) | Y28: =IF(V28="","",IFERROR(V28/$V$15*$Y$15,"")) | Z28: =IF(COUNT(T28:V28)=0,"",SUM(W28:Y28)) | AA28: =IF(Z28="","",Z28*$AA$15) | AB28: =IF(COUNT(F28:J28,N28:P28,T28:V28)=0,"",SUM(M28,S28,AA28)) | AC28: =IF(AB28="","",IFERROR(INDEX(HELPER!$D$8:$D$48,IF(AB28>=HELPER!$B$8,1,MATCH(AB28,HELPER!$B$8:$B$48,-1)+1)),"")) | AD28: =IF(AC28="","",IFERROR(INDEX(HELPER!$G$8:$G$48,MATCH(AC28,HELPER!$F$8:$F$48,-1)),""))
B29: 12 | C29: =IF('INPUT DATA'!K22="","",'INPUT DATA'!K22) | K29: =IF(COUNT($F29:$J29)=0,"",SUM($F29:$J29)) | L29: =IF(COUNT(F29:J29)=0,"",IFERROR(K29/$K$15*$L$15,"")) | M29: =IF(L29="","",L29*$M$15) | Q29: =IF(COUNT(N29:P29)=0,"",SUM(N29:P29)) | R29: =IF(COUNT(N29:P29)=0,"",IFERROR(Q29/$Q$15*$R$15,"")) | S29: =IF(R29="","",R29*$S$15) | W29: =IF(T29="","",IFERROR(T29/$T$15*$W$15,"")) | X29: =IF(U29="","",IFERROR(U29/$U$15*$X$15,"")) | Y29: =IF(V29="","",IFERROR(V29/$V$15*$Y$15,"")) | Z29: =IF(COUNT(T29:V29)=0,"",SUM(W29:Y29)) | AA29: =IF(Z29="","",Z29*$AA$15) | AB29: =IF(COUNT(F29:J29,N29:P29,T29:V29)=0,"",SUM(M29,S29,AA29)) | AC29: =IF(AB29="","",IFERROR(INDEX(HELPER!$D$8:$D$48,IF(AB29>=HELPER!$B$8,1,MATCH(AB29,HELPER!$B$8:$B$48,-1)+1)),"")) | AD29: =IF(AC29="","",IFERROR(INDEX(HELPER!$G$8:$G$48,MATCH(AC29,HELPER!$F$8:$F$48,-1)),""))
... B58: 41 | C58: =IF('INPUT DATA'!K51="","",'INPUT DATA'!K51) | K58: =IF(COUNT($F58:$J58)=0,"",SUM($F58:$J58)) | L58: =IF(COUNT(F58:J58)=0,"",IFERROR(K58/$K$15*$L$15,"")) | M58: =IF(L58="","",L58*$M$15) | Q58: =IF(COUNT(N58:P58)=0,"",SUM(N58:P58)) | R58: =IF(COUNT(N58:P58)=0,"",IFERROR(Q58/$Q$15*$R$15,"")) | S58: =IF(R58="","",R58*$S$15) | W58: =IF(T58="","",IFERROR(T58/$T$15*$W$15,"")) | X58: =IF(U58="","",IFERROR(U58/$U$15*$X$15,"")) | Y58: =IF(V58="","",IFERROR(V58/$V$15*$Y$15,"")) | Z58: =IF(COUNT(T58:V58)=0,"",SUM(W58:Y58)) | AA58: =IF(Z58="","",Z58*$AA$15) | AB58: =IF(COUNT(F58:J58,N58:P58,T58:V58)=0,"",SUM(M58,S58,AA58)) | AC58: =IF(AB58="","",IFERROR(INDEX(HELPER!$D$8:$D$48,IF(AB58>=HELPER!$B$8,1,MATCH(AB58,HELPER!$B$8:$B$48,-1)+1)),"")) | AD58: =IF(AC58="","",IFERROR(INDEX(HELPER!$G$8:$G$48,MATCH(AC58,HELPER!$F$8:$F$48,-1)),""))
B59: 42 | C59: =IF('INPUT DATA'!K52="","",'INPUT DATA'!K52) | K59: =IF(COUNT($F59:$J59)=0,"",SUM($F59:$J59)) | L59: =IF(COUNT(F59:J59)=0,"",IFERROR(K59/$K$15*$L$15,"")) | M59: =IF(L59="","",L59*$M$15) | Q59: =IF(COUNT(N59:P59)=0,"",SUM(N59:P59)) | R59: =IF(COUNT(N59:P59)=0,"",IFERROR(Q59/$Q$15*$R$15,"")) | S59: =IF(R59="","",R59*$S$15) | W59: =IF(T59="","",IFERROR(T59/$T$15*$W$15,"")) | X59: =IF(U59="","",IFERROR(U59/$U$15*$X$15,"")) | Y59: =IF(V59="","",IFERROR(V59/$V$15*$Y$15,"")) | Z59: =IF(COUNT(T59:V59)=0,"",SUM(W59:Y59)) | AA59: =IF(Z59="","",Z59*$AA$15) | AB59: =IF(COUNT(F59:J59,N59:P59,T59:V59)=0,"",SUM(M59,S59,AA59)) | AC59: =IF(AB59="","",IFERROR(INDEX(HELPER!$D$8:$D$48,IFERROR(MATCH(AB59,HELPER!$B$8:$B$48,0),MATCH(AB59,HELPER!$B$8:$B$48,-1)+1)),"")) | AD59: =IF(AC59="","",IFERROR(INDEX(HELPER!$G$8:$G$48,MATCH(AC59,HELPER!$F$8:$F$48,-1)),""))
B60: 43 | C60: =IF('INPUT DATA'!K53="","",'INPUT DATA'!K53) | K60: =IF(COUNT($F60:$J60)=0,"",SUM($F60:$J60)) | L60: =IF(COUNT(F60:J60)=0,"",IFERROR(K60/$K$15*$L$15,"")) | M60: =IF(L60="","",L60*$M$15) | Q60: =IF(COUNT(N60:P60)=0,"",SUM(N60:P60)) | R60: =IF(COUNT(N60:P60)=0,"",IFERROR(Q60/$Q$15*$R$15,"")) | S60: =IF(R60="","",R60*$S$15) | W60: =IF(T60="","",IFERROR(T60/$T$15*$W$15,"")) | X60: =IF(U60="","",IFERROR(U60/$U$15*$X$15,"")) | Y60: =IF(V60="","",IFERROR(V60/$V$15*$Y$15,"")) | Z60: =IF(COUNT(T60:V60)=0,"",SUM(W60:Y60)) | AA60: =IF(Z60="","",Z60*$AA$15) | AB60: =IF(COUNT(F60:J60,N60:P60,T60:V60)=0,"",SUM(M60,S60,AA60)) | AC60: =IF(AB60="","",IFERROR(INDEX(HELPER!$D$8:$D$48,IFERROR(MATCH(AB60,HELPER!$B$8:$B$48,0),MATCH(AB60,HELPER!$B$8:$B$48,-1)+1)),"")) | AD60: =IF(AC60="","",IFERROR(INDEX(HELPER!$G$8:$G$48,MATCH(AC60,HELPER!$F$8:$F$48,-1)),""))
B61: 44 | C61: =IF('INPUT DATA'!K54="","",'INPUT DATA'!K54) | K61: =IF(COUNT($F61:$J61)=0,"",SUM($F61:$J61)) | L61: =IF(COUNT(F61:J61)=0,"",IFERROR(K61/$K$15*$L$15,"")) | M61: =IF(L61="","",L61*$M$15) | Q61: =IF(COUNT(N61:P61)=0,"",SUM(N61:P61)) | R61: =IF(COUNT(N61:P61)=0,"",IFERROR(Q61/$Q$15*$R$15,"")) | S61: =IF(R61="","",R61*$S$15) | W61: =IF(T61="","",IFERROR(T61/$T$15*$W$15,"")) | X61: =IF(U61="","",IFERROR(U61/$U$15*$X$15,"")) | Y61: =IF(V61="","",IFERROR(V61/$V$15*$Y$15,"")) | Z61: =IF(COUNT(T61:V61)=0,"",SUM(W61:Y61)) | AA61: =IF(Z61="","",Z61*$AA$15) | AB61: =IF(COUNT(F61:J61,N61:P61,T61:V61)=0,"",SUM(M61,S61,AA61)) | AC61: =IF(AB61="","",IFERROR(INDEX(HELPER!$D$8:$D$48,IFERROR(MATCH(AB61,HELPER!$B$8:$B$48,0),MATCH(AB61,HELPER!$B$8:$B$48,-1)+1)),"")) | AD61: =IF(AC61="","",IFERROR(INDEX(HELPER!$G$8:$G$48,MATCH(AC61,HELPER!$F$8:$F$48,-1)),""))
B62: 45 | C62: =IF('INPUT DATA'!K55="","",'INPUT DATA'!K55) | K62: =IF(COUNT($F62:$J62)=0,"",SUM($F62:$J62)) | L62: =IF(COUNT(F62:J62)=0,"",IFERROR(K62/$K$15*$L$15,"")) | M62: =IF(L62="","",L62*$M$15) | Q62: =IF(COUNT(N62:P62)=0,"",SUM(N62:P62)) | R62: =IF(COUNT(N62:P62)=0,"",IFERROR(Q62/$Q$15*$R$15,"")) | S62: =IF(R62="","",R62*$S$15) | W62: =IF(T62="","",IFERROR(T62/$T$15*$W$15,"")) | X62: =IF(U62="","",IFERROR(U62/$U$15*$X$15,"")) | Y62: =IF(V62="","",IFERROR(V62/$V$15*$Y$15,"")) | Z62: =IF(COUNT(T62:V62)=0,"",SUM(W62:Y62)) | AA62: =IF(Z62="","",Z62*$AA$15) | AB62: =IF(COUNT(F62:J62,N62:P62,T62:V62)=0,"",SUM(M62,S62,AA62)) | AC62: =IF(AB62="","",IFERROR(INDEX(HELPER!$D$8:$D$48,IFERROR(MATCH(AB62,HELPER!$B$8:$B$48,0),MATCH(AB62,HELPER!$B$8:$B$48,-1)+1)),"")) | AD62: =IF(AC62="","",IFERROR(INDEX(HELPER!$G$8:$G$48,MATCH(AC62,HELPER!$F$8:$F$48,-1)),""))
B63: 46 | C63: =IF('INPUT DATA'!K56="","",'INPUT DATA'!K56) | K63: =IF(COUNT($F63:$J63)=0,"",SUM($F63:$J63)) | L63: =IF(COUNT(F63:J63)=0,"",IFERROR(K63/$K$15*$L$15,"")) | M63: =IF(L63="","",L63*$M$15) | Q63: =IF(COUNT(N63:P63)=0,"",SUM(N63:P63)) | R63: =IF(COUNT(N63:P63)=0,"",IFERROR(Q63/$Q$15*$R$15,"")) | S63: =IF(R63="","",R63*$S$15) | W63: =IF(T63="","",IFERROR(T63/$T$15*$W$15,"")) | X63: =IF(U63="","",IFERROR(U63/$U$15*$X$15,"")) | Y63: =IF(V63="","",IFERROR(V63/$V$15*$Y$15,"")) | Z63: =IF(COUNT(T63:V63)=0,"",SUM(W63:Y63)) | AA63: =IF(Z63="","",Z63*$AA$15) | AB63: =IF(COUNT(F63:J63,N63:P63,T63:V63)=0,"",SUM(M63,S63,AA63)) | AC63: =IF(AB63="","",IFERROR(INDEX(HELPER!$D$8:$D$48,IFERROR(MATCH(AB63,HELPER!$B$8:$B$48,0),MATCH(AB63,HELPER!$B$8:$B$48,-1)+1)),"")) | AD63: =IF(AC63="","",IFERROR(INDEX(HELPER!$G$8:$G$48,MATCH(AC63,HELPER!$F$8:$F$48,-1)),""))
B64: 47 | C64: =IF('INPUT DATA'!K57="","",'INPUT DATA'!K57) | K64: =IF(COUNT($F64:$J64)=0,"",SUM($F64:$J64)) | L64: =IF(COUNT(F64:J64)=0,"",IFERROR(K64/$K$15*$L$15,"")) | M64: =IF(L64="","",L64*$M$15) | Q64: =IF(COUNT(N64:P64)=0,"",SUM(N64:P64)) | R64: =IF(COUNT(N64:P64)=0,"",IFERROR(Q64/$Q$15*$R$15,"")) | S64: =IF(R64="","",R64*$S$15) | W64: =IF(T64="","",IFERROR(T64/$T$15*$W$15,"")) | X64: =IF(U64="","",IFERROR(U64/$U$15*$X$15,"")) | Y64: =IF(V64="","",IFERROR(V64/$V$15*$Y$15,"")) | Z64: =IF(COUNT(T64:V64)=0,"",SUM(W64:Y64)) | AA64: =IF(Z64="","",Z64*$AA$15) | AB64: =IF(COUNT(F64:J64,N64:P64,T64:V64)=0,"",SUM(M64,S64,AA64)) | AC64: =IF(AB64="","",IFERROR(INDEX(HELPER!$D$8:$D$48,IFERROR(MATCH(AB64,HELPER!$B$8:$B$48,0),MATCH(AB64,HELPER!$B$8:$B$48,-1)+1)),"")) | AD64: =IF(AC64="","",IFERROR(INDEX(HELPER!$G$8:$G$48,MATCH(AC64,HELPER!$F$8:$F$48,-1)),""))
B65: 48 | C65: =IF('INPUT DATA'!K58="","",'INPUT DATA'!K58) | K65: =IF(COUNT($F65:$J65)=0,"",SUM($F65:$J65)) | L65: =IF(COUNT(F65:J65)=0,"",IFERROR(K65/$K$15*$L$15,"")) | M65: =IF(L65="","",L65*$M$15) | Q65: =IF(COUNT(N65:P65)=0,"",SUM(N65:P65)) | R65: =IF(COUNT(N65:P65)=0,"",IFERROR(Q65/$Q$15*$R$15,"")) | S65: =IF(R65="","",R65*$S$15) | W65: =IF(T65="","",IFERROR(T65/$T$15*$W$15,"")) | X65: =IF(U65="","",IFERROR(U65/$U$15*$X$15,"")) | Y65: =IF(V65="","",IFERROR(V65/$V$15*$Y$15,"")) | Z65: =IF(COUNT(T65:V65)=0,"",SUM(W65:Y65)) | AA65: =IF(Z65="","",Z65*$AA$15) | AB65: =IF(COUNT(F65:J65,N65:P65,T65:V65)=0,"",SUM(M65,S65,AA65)) | AC65: =IF(AB65="","",IFERROR(INDEX(HELPER!$D$8:$D$48,IFERROR(MATCH(AB65,HELPER!$B$8:$B$48,0),MATCH(AB65,HELPER!$B$8:$B$48,-1)+1)),"")) | AD65: =IF(AC65="","",IFERROR(INDEX(HELPER!$G$8:$G$48,MATCH(AC65,HELPER!$F$8:$F$48,-1)),""))
B66: 49 | C66: =IF('INPUT DATA'!K59="","",'INPUT DATA'!K59) | K66: =IF(COUNT($F66:$J66)=0,"",SUM($F66:$J66)) | L66: =IF(COUNT(F66:J66)=0,"",IFERROR(K66/$K$15*$L$15,"")) | M66: =IF(L66="","",L66*$M$15) | Q66: =IF(COUNT(N66:P66)=0,"",SUM(N66:P66)) | R66: =IF(COUNT(N66:P66)=0,"",IFERROR(Q66/$Q$15*$R$15,"")) | S66: =IF(R66="","",R66*$S$15) | W66: =IF(T66="","",IFERROR(T66/$T$15*$W$15,"")) | X66: =IF(U66="","",IFERROR(U66/$U$15*$X$15,"")) | Y66: =IF(V66="","",IFERROR(V66/$V$15*$Y$15,"")) | Z66: =IF(COUNT(T66:V66)=0,"",SUM(W66:Y66)) | AA66: =IF(Z66="","",Z66*$AA$15) | AB66: =IF(COUNT(F66:J66,N66:P66,T66:V66)=0,"",SUM(M66,S66,AA66)) | AC66: =IF(AB66="","",IFERROR(INDEX(HELPER!$D$8:$D$48,IFERROR(MATCH(AB66,HELPER!$B$8:$B$48,0),MATCH(AB66,HELPER!$B$8:$B$48,-1)+1)),"")) | AD66: =IF(AC66="","",IFERROR(INDEX(HELPER!$G$8:$G$48,MATCH(AC66,HELPER!$F$8:$F$48,-1)),""))
B67: 50 | C67: =IF('INPUT DATA'!K60="","",'INPUT DATA'!K60) | K67: =IF(COUNT($F67:$J67)=0,"",SUM($F67:$J67)) | L67: =IF(COUNT(F67:J67)=0,"",IFERROR(K67/$K$15*$L$15,"")) | M67: =IF(L67="","",L67*$M$15) | Q67: =IF(COUNT(N67:P67)=0,"",SUM(N67:P67)) | R67: =IF(COUNT(N67:P67)=0,"",IFERROR(Q67/$Q$15*$R$15,"")) | S67: =IF(R67="","",R67*$S$15) | W67: =IF(T67="","",IFERROR(T67/$T$15*$W$15,"")) | X67: =IF(U67="","",IFERROR(U67/$U$15*$X$15,"")) | Y67: =IF(V67="","",IFERROR(V67/$V$15*$Y$15,"")) | Z67: =IF(COUNT(T67:V67)=0,"",SUM(W67:Y67)) | AA67: =IF(Z67="","",Z67*$AA$15) | AB67: =IF(COUNT(F67:J67,N67:P67,T67:V67)=0,"",SUM(M67,S67,AA67)) | AC67: =IF(AB67="","",IFERROR(INDEX(HELPER!$D$8:$D$48,IFERROR(MATCH(AB67,HELPER!$B$8:$B$48,0),MATCH(AB67,HELPER!$B$8:$B$48,-1)+1)),"")) | AD67: =IF(AC67="","",IFERROR(INDEX(HELPER!$G$8:$G$48,MATCH(AC67,HELPER!$F$8:$F$48,-1)),""))
B68: FEMALE
B69: 1 | C69: =IF('INPUT DATA'!N11="","",'INPUT DATA'!N11) | K69: =IF(COUNT($F69:$J69)=0,"",SUM($F69:$J69)) | L69: =IF(COUNT(F69:J69)=0,"",IFERROR(K69/$K$15*$L$15,"")) | M69: =IF(L69="","",L69*$M$15) | Q69: =IF(COUNT(N69:P69)=0,"",SUM(N69:P69)) | R69: =IF(COUNT(N69:P69)=0,"",IFERROR(Q69/$Q$15*$R$15,"")) | S69: =IF(R69="","",R69*$S$15) | W69: =IF(T69="","",IFERROR(T69/$T$15*$W$15,"")) | X69: =IF(U69="","",IFERROR(U69/$U$15*$X$15,"")) | Y69: =IF(V69="","",IFERROR(V69/$V$15*$Y$15,"")) | Z69: =IF(COUNT(T69:V69)=0,"",SUM(W69:Y69)) | AA69: =IF(Z69="","",Z69*$AA$15) | AB69: =IF(COUNT(F69:J69,N69:P69,T69:V69)=0,"",SUM(M69,S69,AA69)) | AC69: =IF(AB69="","",IFERROR(INDEX(HELPER!$D$8:$D$48,IFERROR(MATCH(AB69,HELPER!$B$8:$B$48,0),MATCH(AB69,HELPER!$B$8:$B$48,-1)+1)),"")) | AD69: =IF(AC69="","",IFERROR(INDEX(HELPER!$G$8:$G$48,MATCH(AC69,HELPER!$F$8:$F$48,-1)),""))
B70: 2 | C70: =IF('INPUT DATA'!N12="","",'INPUT DATA'!N12) | K70: =IF(COUNT($F70:$J70)=0,"",SUM($F70:$J70)) | L70: =IF(COUNT(F70:J70)=0,"",IFERROR(K70/$K$15*$L$15,"")) | M70: =IF(L70="","",L70*$M$15) | Q70: =IF(COUNT(N70:P70)=0,"",SUM(N70:P70)) | R70: =IF(COUNT(N70:P70)=0,"",IFERROR(Q70/$Q$15*$R$15,"")) | S70: =IF(R70="","",R70*$S$15) | W70: =IF(T70="","",IFERROR(T70/$T$15*$W$15,"")) | X70: =IF(U70="","",IFERROR(U70/$U$15*$X$15,"")) | Y70: =IF(V70="","",IFERROR(V70/$V$15*$Y$15,"")) | Z70: =IF(COUNT(T70:V70)=0,"",SUM(W70:Y70)) | AA70: =IF(Z70="","",Z70*$AA$15) | AB70: =IF(COUNT(F70:J70,N70:P70,T70:V70)=0,"",SUM(M70,S70,AA70)) | AC70: =IF(AB70="","",IFERROR(INDEX(HELPER!$D$8:$D$48,IFERROR(MATCH(AB70,HELPER!$B$8:$B$48,0),MATCH(AB70,HELPER!$B$8:$B$48,-1)+1)),"")) | AD70: =IF(AC70="","",IFERROR(INDEX(HELPER!$G$8:$G$48,MATCH(AC70,HELPER!$F$8:$F$48,-1)),""))
B71: 3 | C71: =IF('INPUT DATA'!N13="","",'INPUT DATA'!N13) | K71: =IF(COUNT($F71:$J71)=0,"",SUM($F71:$J71)) | L71: =IF(COUNT(F71:J71)=0,"",IFERROR(K71/$K$15*$L$15,"")) | M71: =IF(L71="","",L71*$M$15) | Q71: =IF(COUNT(N71:P71)=0,"",SUM(N71:P71)) | R71: =IF(COUNT(N71:P71)=0,"",IFERROR(Q71/$Q$15*$R$15,"")) | S71: =IF(R71="","",R71*$S$15) | W71: =IF(T71="","",IFERROR(T71/$T$15*$W$15,"")) | X71: =IF(U71="","",IFERROR(U71/$U$15*$X$15,"")) | Y71: =IF(V71="","",IFERROR(V71/$V$15*$Y$15,"")) | Z71: =IF(COUNT(T71:V71)=0,"",SUM(W71:Y71)) | AA71: =IF(Z71="","",Z71*$AA$15) | AB71: =IF(COUNT(F71:J71,N71:P71,T71:V71)=0,"",SUM(M71,S71,AA71)) | AC71: =IF(AB71="","",IFERROR(INDEX(HELPER!$D$8:$D$48,IFERROR(MATCH(AB71,HELPER!$B$8:$B$48,0),MATCH(AB71,HELPER!$B$8:$B$48,-1)+1)),"")) | AD71: =IF(AC71="","",IFERROR(INDEX(HELPER!$G$8:$G$48,MATCH(AC71,HELPER!$F$8:$F$48,-1)),""))
B72: 4 | C72: =IF('INPUT DATA'!N14="","",'INPUT DATA'!N14) | K72: =IF(COUNT($F72:$J72)=0,"",SUM($F72:$J72)) | L72: =IF(COUNT(F72:J72)=0,"",IFERROR(K72/$K$15*$L$15,"")) | M72: =IF(L72="","",L72*$M$15) | Q72: =IF(COUNT(N72:P72)=0,"",SUM(N72:P72)) | R72: =IF(COUNT(N72:P72)=0,"",IFERROR(Q72/$Q$15*$R$15,"")) | S72: =IF(R72="","",R72*$S$15) | W72: =IF(T72="","",IFERROR(T72/$T$15*$W$15,"")) | X72: =IF(U72="","",IFERROR(U72/$U$15*$X$15,"")) | Y72: =IF(V72="","",IFERROR(V72/$V$15*$Y$15,"")) | Z72: =IF(COUNT(T72:V72)=0,"",SUM(W72:Y72)) | AA72: =IF(Z72="","",Z72*$AA$15) | AB72: =IF(COUNT(F72:J72,N72:P72,T72:V72)=0,"",SUM(M72,S72,AA72)) | AC72: =IF(AB72="","",IFERROR(INDEX(HELPER!$D$8:$D$48,IFERROR(MATCH(AB72,HELPER!$B$8:$B$48,0),MATCH(AB72,HELPER!$B$8:$B$48,-1)+1)),"")) | AD72: =IF(AC72="","",IFERROR(INDEX(HELPER!$G$8:$G$48,MATCH(AC72,HELPER!$F$8:$F$48,-1)),""))
B73: 5 | C73: =IF('INPUT DATA'!N15="","",'INPUT DATA'!N15) | K73: =IF(COUNT($F73:$J73)=0,"",SUM($F73:$J73)) | L73: =IF(COUNT(F73:J73)=0,"",IFERROR(K73/$K$15*$L$15,"")) | M73: =IF(L73="","",L73*$M$15) | Q73: =IF(COUNT(N73:P73)=0,"",SUM(N73:P73)) | R73: =IF(COUNT(N73:P73)=0,"",IFERROR(Q73/$Q$15*$R$15,"")) | S73: =IF(R73="","",R73*$S$15) | W73: =IF(T73="","",IFERROR(T73/$T$15*$W$15,"")) | X73: =IF(U73="","",IFERROR(U73/$U$15*$X$15,"")) | Y73: =IF(V73="","",IFERROR(V73/$V$15*$Y$15,"")) | Z73: =IF(COUNT(T73:V73)=0,"",SUM(W73:Y73)) | AA73: =IF(Z73="","",Z73*$AA$15) | AB73: =IF(COUNT(F73:J73,N73:P73,T73:V73)=0,"",SUM(M73,S73,AA73)) | AC73: =IF(AB73="","",IFERROR(INDEX(HELPER!$D$8:$D$48,IFERROR(MATCH(AB73,HELPER!$B$8:$B$48,0),MATCH(AB73,HELPER!$B$8:$B$48,-1)+1)),"")) | AD73: =IF(AC73="","",IFERROR(INDEX(HELPER!$G$8:$G$48,MATCH(AC73,HELPER!$F$8:$F$48,-1)),""))
B74: 6 | C74: =IF('INPUT DATA'!N16="","",'INPUT DATA'!N16) | K74: =IF(COUNT($F74:$J74)=0,"",SUM($F74:$J74)) | L74: =IF(COUNT(F74:J74)=0,"",IFERROR(K74/$K$15*$L$15,"")) | M74: =IF(L74="","",L74*$M$15) | Q74: =IF(COUNT(N74:P74)=0,"",SUM(N74:P74)) | R74: =IF(COUNT(N74:P74)=0,"",IFERROR(Q74/$Q$15*$R$15,"")) | S74: =IF(R74="","",R74*$S$15) | W74: =IF(T74="","",IFERROR(T74/$T$15*$W$15,"")) | X74: =IF(U74="","",IFERROR(U74/$U$15*$X$15,"")) | Y74: =IF(V74="","",IFERROR(V74/$V$15*$Y$15,"")) | Z74: =IF(COUNT(T74:V74)=0,"",SUM(W74:Y74)) | AA74: =IF(Z74="","",Z74*$AA$15) | AB74: =IF(COUNT(F74:J74,N74:P74,T74:V74)=0,"",SUM(M74,S74,AA74)) | AC74: =IF(AB74="","",IFERROR(INDEX(HELPER!$D$8:$D$48,IFERROR(MATCH(AB74,HELPER!$B$8:$B$48,0),MATCH(AB74,HELPER!$B$8:$B$48,-1)+1)),"")) | AD74: =IF(AC74="","",IFERROR(INDEX(HELPER!$G$8:$G$48,MATCH(AC74,HELPER!$F$8:$F$48,-1)),""))
B75: 7 | C75: =IF('INPUT DATA'!N17="","",'INPUT DATA'!N17) | K75: =IF(COUNT($F75:$J75)=0,"",SUM($F75:$J75)) | L75: =IF(COUNT(F75:J75)=0,"",IFERROR(K75/$K$15*$L$15,"")) | M75: =IF(L75="","",L75*$M$15) | Q75: =IF(COUNT(N75:P75)=0,"",SUM(N75:P75)) | R75: =IF(COUNT(N75:P75)=0,"",IFERROR(Q75/$Q$15*$R$15,"")) | S75: =IF(R75="","",R75*$S$15) | W75: =IF(T75="","",IFERROR(T75/$T$15*$W$15,"")) | X75: =IF(U75="","",IFERROR(U75/$U$15*$X$15,"")) | Y75: =IF(V75="","",IFERROR(V75/$V$15*$Y$15,"")) | Z75: =IF(COUNT(T75:V75)=0,"",SUM(W75:Y75)) | AA75: =IF(Z75="","",Z75*$AA$15) | AB75: =IF(COUNT(F75:J75,N75:P75,T75:V75)=0,"",SUM(M75,S75,AA75)) | AC75: =IF(AB75="","",IFERROR(INDEX(HELPER!$D$8:$D$48,IFERROR(MATCH(AB75,HELPER!$B$8:$B$48,0),MATCH(AB75,HELPER!$B$8:$B$48,-1)+1)),"")) | AD75: =IF(AC75="","",IFERROR(INDEX(HELPER!$G$8:$G$48,MATCH(AC75,HELPER!$F$8:$F$48,-1)),""))
...

Sheet TERM 2
B2: CLASS RECORD
E5: REGION | F5: =IF('INPUT DATA'!E10="","",'INPUT DATA'!E10) | Q5: DIVISION | R5: =IF('INPUT DATA'!E11="","",'INPUT DATA'!E11) | Y5: SCHOOL ID | Z5: =IF('INPUT DATA'!E13="","",'INPUT DATA'!E13)
E7: SCHOOL NAME | F7: =IF('INPUT DATA'!E14="","",'INPUT DATA'!E14) | Y7: SCHOOL YEAR | Z7: =IF('INPUT DATA'!E15="","",'INPUT DATA'!E15)
B10: SECOND TERM | F10: GRADE LEVEL | J10: =IF('INPUT DATA'!E25="","",'INPUT DATA'!E25) | N10: TEACHER | Q10: =IF('INPUT DATA'!E23="","",'INPUT DATA'!E23) | Y10: SUBJECT | AA10: =IF('INPUT DATA'!E24="","",'INPUT DATA'!E24)
F11: SECTION | J11: =IF('INPUT DATA'!E26="","",'INPUT DATA'!E26)
F12: WRITTEN / ORAL WORKS (WWs) | N12: PRODUCT / PERFORMANCE TASKS (PTs) | T12: EXAMINATIONS (EXs) | AB12: Initial Grade | AC12: Term Grade | AD12: Descriptor
F14: 1 | G14: 2 | H14: 3 | I14: 4 | J14: 5 | K14: Total | L14: PS | M14: WS | N14: 1 | O14: 2 | P14: 3 | Q14: Total | R14: PS | S14: WS | T14: ST1 | U14: ST2 | V14: TE | W14: WS ST1 | X14: WS ST2 | Y14: WS TE | Z14: PS | AA14: WS
B15: HIGHEST POSSIBLE SCORE | K15: =IF(COUNT(F15:J15)=0,"",SUM(F15:J15)) | L15: 100 | M15: 0.2 | Q15: =IF(COUNT(N15:P15)=0,"",SUM(N15:P15)) | R15: 100 | S15: 0.6 | W15: 30 | X15: 30 | Y15: 40 | Z15: 100 | AA15: 0.2
B16: LEARNERS' NAMES
B17: MALE
B18: 1 | C18: =IF('INPUT DATA'!K11="","",'INPUT DATA'!K11) | K18: =IF(COUNT($F18:$J18)=0,"",SUM($F18:$J18)) | L18: =IF(COUNT(F18:J18)=0,"",IFERROR(K18/$K$15*$L$15,"")) | M18: =IF(L18="","",L18*$M$15) | Q18: =IF(COUNT(N18:P18)=0,"",SUM(N18:P18)) | R18: =IF(COUNT(N18:P18)=0,"",IFERROR(Q18/$Q$15*$R$15,"")) | S18: =IF(R18="","",R18*$S$15) | W18: =IF(T18="","",IFERROR(T18/$T$15*$W$15,"")) | X18: =IF(U18="","",IFERROR(U18/$U$15*$X$15,"")) | Y18: =IF(V18="","",IFERROR(V18/$V$15*$Y$15,"")) | Z18: =IF(COUNT(T18:V18)=0,"",SUM(W18:Y18)) | AA18: =IF(Z18="","",Z18*$AA$15) | AB18: =IF(COUNT(F18:J18,N18:P18,T18:V18)=0,"",SUM(M18,S18,AA18)) | AC18: =IF(AB18="","",IFERROR(INDEX(HELPER!$D$8:$D$48,IF(AB18>=HELPER!$B$8,1,MATCH(AB18,HELPER!$B$8:$B$48,-1)+1)),"")) | AD18: =IF(AC18="","",IFERROR(INDEX(HELPER!$G$8:$G$48,MATCH(AC18,HELPER!$F$8:$F$48,-1)),""))
B19: 2 | C19: =IF('INPUT DATA'!K12="","",'INPUT DATA'!K12) | K19: =IF(COUNT($F19:$J19)=0,"",SUM($F19:$J19)) | L19: =IF(COUNT(F19:J19)=0,"",IFERROR(K19/$K$15*$L$15,"")) | M19: =IF(L19="","",L19*$M$15) | Q19: =IF(COUNT(N19:P19)=0,"",SUM(N19:P19)) | R19: =IF(COUNT(N19:P19)=0,"",IFERROR(Q19/$Q$15*$R$15,"")) | S19: =IF(R19="","",R19*$S$15) | W19: =IF(T19="","",IFERROR(T19/$T$15*$W$15,"")) | X19: =IF(U19="","",IFERROR(U19/$U$15*$X$15,"")) | Y19: =IF(V19="","",IFERROR(V19/$V$15*$Y$15,"")) | Z19: =IF(COUNT(T19:V19)=0,"",SUM(W19:Y19)) | AA19: =IF(Z19="","",Z19*$AA$15) | AB19: =IF(COUNT(F19:J19,N19:P19,T19:V19)=0,"",SUM(M19,S19,AA19)) | AC19: =IF(AB19="","",IFERROR(INDEX(HELPER!$D$8:$D$48,IF(AB19>=HELPER!$B$8,1,MATCH(AB19,HELPER!$B$8:$B$48,-1)+1)),"")) | AD19: =IF(AC19="","",IFERROR(INDEX(HELPER!$G$8:$G$48,MATCH(AC19,HELPER!$F$8:$F$48,-1)),""))
B20: 3 | C20: =IF('INPUT DATA'!K13="","",'INPUT DATA'!K13) | K20: =IF(COUNT($F20:$J20)=0,"",SUM($F20:$J20)) | L20: =IF(COUNT(F20:J20)=0,"",IFERROR(K20/$K$15*$L$15,"")) | M20: =IF(L20="","",L20*$M$15) | Q20: =IF(COUNT(N20:P20)=0,"",SUM(N20:P20)) | R20: =IF(COUNT(N20:P20)=0,"",IFERROR(Q20/$Q$15*$R$15,"")) | S20: =IF(R20="","",R20*$S$15) | W20: =IF(T20="","",IFERROR(T20/$T$15*$W$15,"")) | X20: =IF(U20="","",IFERROR(U20/$U$15*$X$15,"")) | Y20: =IF(V20="","",IFERROR(V20/$V$15*$Y$15,"")) | Z20: =IF(COUNT(T20:V20)=0,"",SUM(W20:Y20)) | AA20: =IF(Z20="","",Z20*$AA$15) | AB20: =IF(COUNT(F20:J20,N20:P20,T20:V20)=0,"",SUM(M20,S20,AA20)) | AC20: =IF(AB20="","",IFERROR(INDEX(HELPER!$D$8:$D$48,IF(AB20>=HELPER!$B$8,1,MATCH(AB20,HELPER!$B$8:$B$48,-1)+1)),"")) | AD20: =IF(AC20="","",IFERROR(INDEX(HELPER!$G$8:$G$48,MATCH(AC20,HELPER!$F$8:$F$48,-1)),""))
B21: 4 | C21: =IF('INPUT DATA'!K14="","",'INPUT DATA'!K14) | K21: =IF(COUNT($F21:$J21)=0,"",SUM($F21:$J21)) | L21: =IF(COUNT(F21:J21)=0,"",IFERROR(K21/$K$15*$L$15,"")) | M21: =IF(L21="","",L21*$M$15) | Q21: =IF(COUNT(N21:P21)=0,"",SUM(N21:P21)) | R21: =IF(COUNT(N21:P21)=0,"",IFERROR(Q21/$Q$15*$R$15,"")) | S21: =IF(R21="","",R21*$S$15) | W21: =IF(T21="","",IFERROR(T21/$T$15*$W$15,"")) | X21: =IF(U21="","",IFERROR(U21/$U$15*$X$15,"")) | Y21: =IF(V21="","",IFERROR(V21/$V$15*$Y$15,"")) | Z21: =IF(COUNT(T21:V21)=0,"",SUM(W21:Y21)) | AA21: =IF(Z21="","",Z21*$AA$15) | AB21: =IF(COUNT(F21:J21,N21:P21,T21:V21)=0,"",SUM(M21,S21,AA21)) | AC21: =IF(AB21="","",IFERROR(INDEX(HELPER!$D$8:$D$48,IF(AB21>=HELPER!$B$8,1,MATCH(AB21,HELPER!$B$8:$B$48,-1)+1)),"")) | AD21: =IF(AC21="","",IFERROR(INDEX(HELPER!$G$8:$G$48,MATCH(AC21,HELPER!$F$8:$F$48,-1)),""))
B22: 5 | C22: =IF('INPUT DATA'!K15="","",'INPUT DATA'!K15) | K22: =IF(COUNT($F22:$J22)=0,"",SUM($F22:$J22)) | L22: =IF(COUNT(F22:J22)=0,"",IFERROR(K22/$K$15*$L$15,"")) | M22: =IF(L22="","",L22*$M$15) | Q22: =IF(COUNT(N22:P22)=0,"",SUM(N22:P22)) | R22: =IF(COUNT(N22:P22)=0,"",IFERROR(Q22/$Q$15*$R$15,"")) | S22: =IF(R22="","",R22*$S$15) | W22: =IF(T22="","",IFERROR(T22/$T$15*$W$15,"")) | X22: =IF(U22="","",IFERROR(U22/$U$15*$X$15,"")) | Y22: =IF(V22="","",IFERROR(V22/$V$15*$Y$15,"")) | Z22: =IF(COUNT(T22:V22)=0,"",SUM(W22:Y22)) | AA22: =IF(Z22="","",Z22*$AA$15) | AB22: =IF(COUNT(F22:J22,N22:P22,T22:V22)=0,"",SUM(M22,S22,AA22)) | AC22: =IF(AB22="","",IFERROR(INDEX(HELPER!$D$8:$D$48,IF(AB22>=HELPER!$B$8,1,MATCH(AB22,HELPER!$B$8:$B$48,-1)+1)),"")) | AD22: =IF(AC22="","",IFERROR(INDEX(HELPER!$G$8:$G$48,MATCH(AC22,HELPER!$F$8:$F$48,-1)),""))
B23: 6 | C23: =IF('INPUT DATA'!K16="","",'INPUT DATA'!K16) | K23: =IF(COUNT($F23:$J23)=0,"",SUM($F23:$J23)) | L23: =IF(COUNT(F23:J23)=0,"",IFERROR(K23/$K$15*$L$15,"")) | M23: =IF(L23="","",L23*$M$15) | Q23: =IF(COUNT(N23:P23)=0,"",SUM(N23:P23)) | R23: =IF(COUNT(N23:P23)=0,"",IFERROR(Q23/$Q$15*$R$15,"")) | S23: =IF(R23="","",R23*$S$15) | W23: =IF(T23="","",IFERROR(T23/$T$15*$W$15,"")) | X23: =IF(U23="","",IFERROR(U23/$U$15*$X$15,"")) | Y23: =IF(V23="","",IFERROR(V23/$V$15*$Y$15,"")) | Z23: =IF(COUNT(T23:V23)=0,"",SUM(W23:Y23)) | AA23: =IF(Z23="","",Z23*$AA$15) | AB23: =IF(COUNT(F23:J23,N23:P23,T23:V23)=0,"",SUM(M23,S23,AA23)) | AC23: =IF(AB23="","",IFERROR(INDEX(HELPER!$D$8:$D$48,IF(AB23>=HELPER!$B$8,1,MATCH(AB23,HELPER!$B$8:$B$48,-1)+1)),"")) | AD23: =IF(AC23="","",IFERROR(INDEX(HELPER!$G$8:$G$48,MATCH(AC23,HELPER!$F$8:$F$48,-1)),""))
B24: 7 | C24: =IF('INPUT DATA'!K17="","",'INPUT DATA'!K17) | K24: =IF(COUNT($F24:$J24)=0,"",SUM($F24:$J24)) | L24: =IF(COUNT(F24:J24)=0,"",IFERROR(K24/$K$15*$L$15,"")) | M24: =IF(L24="","",L24*$M$15) | Q24: =IF(COUNT(N24:P24)=0,"",SUM(N24:P24)) | R24: =IF(COUNT(N24:P24)=0,"",IFERROR(Q24/$Q$15*$R$15,"")) | S24: =IF(R24="","",R24*$S$15) | W24: =IF(T24="","",IFERROR(T24/$T$15*$W$15,"")) | X24: =IF(U24="","",IFERROR(U24/$U$15*$X$15,"")) | Y24: =IF(V24="","",IFERROR(V24/$V$15*$Y$15,"")) | Z24: =IF(COUNT(T24:V24)=0,"",SUM(W24:Y24)) | AA24: =IF(Z24="","",Z24*$AA$15) | AB24: =IF(COUNT(F24:J24,N24:P24,T24:V24)=0,"",SUM(M24,S24,AA24)) | AC24: =IF(AB24="","",IFERROR(INDEX(HELPER!$D$8:$D$48,IF(AB24>=HELPER!$B$8,1,MATCH(AB24,HELPER!$B$8:$B$48,-1)+1)),"")) | AD24: =IF(AC24="","",IFERROR(INDEX(HELPER!$G$8:$G$48,MATCH(AC24,HELPER!$F$8:$F$48,-1)),""))
B25: 8 | C25: =IF('INPUT DATA'!K18="","",'INPUT DATA'!K18) | K25: =IF(COUNT($F25:$J25)=0,"",SUM($F25:$J25)) | L25: =IF(COUNT(F25:J25)=0,"",IFERROR(K25/$K$15*$L$15,"")) | M25: =IF(L25="","",L25*$M$15) | Q25: =IF(COUNT(N25:P25)=0,"",SUM(N25:P25)) | R25: =IF(COUNT(N25:P25)=0,"",IFERROR(Q25/$Q$15*$R$15,"")) | S25: =IF(R25="","",R25*$S$15) | W25: =IF(T25="","",IFERROR(T25/$T$15*$W$15,"")) | X25: =IF(U25="","",IFERROR(U25/$U$15*$X$15,"")) | Y25: =IF(V25="","",IFERROR(V25/$V$15*$Y$15,"")) | Z25: =IF(COUNT(T25:V25)=0,"",SUM(W25:Y25)) | AA25: =IF(Z25="","",Z25*$AA$15) | AB25: =IF(COUNT(F25:J25,N25:P25,T25:V25)=0,"",SUM(M25,S25,AA25)) | AC25: =IF(AB25="","",IFERROR(INDEX(HELPER!$D$8:$D$48,IF(AB25>=HELPER!$B$8,1,MATCH(AB25,HELPER!$B$8:$B$48,-1)+1)),"")) | AD25: =IF(AC25="","",IFERROR(INDEX(HELPER!$G$8:$G$48,MATCH(AC25,HELPER!$F$8:$F$48,-1)),""))
B26: 9 | C26: =IF('INPUT DATA'!K19="","",'INPUT DATA'!K19) | K26: =IF(COUNT($F26:$J26)=0,"",SUM($F26:$J26)) | L26: =IF(COUNT(F26:J26)=0,"",IFERROR(K26/$K$15*$L$15,"")) | M26: =IF(L26="","",L26*$M$15) | Q26: =IF(COUNT(N26:P26)=0,"",SUM(N26:P26)) | R26: =IF(COUNT(N26:P26)=0,"",IFERROR(Q26/$Q$15*$R$15,"")) | S26: =IF(R26="","",R26*$S$15) | W26: =IF(T26="","",IFERROR(T26/$T$15*$W$15,"")) | X26: =IF(U26="","",IFERROR(U26/$U$15*$X$15,"")) | Y26: =IF(V26="","",IFERROR(V26/$V$15*$Y$15,"")) | Z26: =IF(COUNT(T26:V26)=0,"",SUM(W26:Y26)) | AA26: =IF(Z26="","",Z26*$AA$15) | AB26: =IF(COUNT(F26:J26,N26:P26,T26:V26)=0,"",SUM(M26,S26,AA26)) | AC26: =IF(AB26="","",IFERROR(INDEX(HELPER!$D$8:$D$48,IF(AB26>=HELPER!$B$8,1,MATCH(AB26,HELPER!$B$8:$B$48,-1)+1)),"")) | AD26: =IF(AC26="","",IFERROR(INDEX(HELPER!$G$8:$G$48,MATCH(AC26,HELPER!$F$8:$F$48,-1)),""))
B27: 10 | C27: =IF('INPUT DATA'!K20="","",'INPUT DATA'!K20) | K27: =IF(COUNT($F27:$J27)=0,"",SUM($F27:$J27)) | L27: =IF(COUNT(F27:J27)=0,"",IFERROR(K27/$K$15*$L$15,"")) | M27: =IF(L27="","",L27*$M$15) | Q27: =IF(COUNT(N27:P27)=0,"",SUM(N27:P27)) | R27: =IF(COUNT(N27:P27)=0,"",IFERROR(Q27/$Q$15*$R$15,"")) | S27: =IF(R27="","",R27*$S$15) | W27: =IF(T27="","",IFERROR(T27/$T$15*$W$15,"")) | X27: =IF(U27="","",IFERROR(U27/$U$15*$X$15,"")) | Y27: =IF(V27="","",IFERROR(V27/$V$15*$Y$15,"")) | Z27: =IF(COUNT(T27:V27)=0,"",SUM(W27:Y27)) | AA27: =IF(Z27="","",Z27*$AA$15) | AB27: =IF(COUNT(F27:J27,N27:P27,T27:V27)=0,"",SUM(M27,S27,AA27)) | AC27: =IF(AB27="","",IFERROR(INDEX(HELPER!$D$8:$D$48,IF(AB27>=HELPER!$B$8,1,MATCH(AB27,HELPER!$B$8:$B$48,-1)+1)),"")) | AD27: =IF(AC27="","",IFERROR(INDEX(HELPER!$G$8:$G$48,MATCH(AC27,HELPER!$F$8:$F$48,-1)),""))
B28: 11 | C28: =IF('INPUT DATA'!K21="","",'INPUT DATA'!K21) | K28: =IF(COUNT($F28:$J28)=0,"",SUM($F28:$J28)) | L28: =IF(COUNT(F28:J28)=0,"",IFERROR(K28/$K$15*$L$15,"")) | M28: =IF(L28="","",L28*$M$15) | Q28: =IF(COUNT(N28:P28)=0,"",SUM(N28:P28)) | R28: =IF(COUNT(N28:P28)=0,"",IFERROR(Q28/$Q$15*$R$15,"")) | S28: =IF(R28="","",R28*$S$15) | W28: =IF(T28="","",IFERROR(T28/$T$15*$W$15,"")) | X28: =IF(U28="","",IFERROR(U28/$U$15*$X$15,"")) | Y28: =IF(V28="","",IFERROR(V28/$V$15*$Y$15,"")) | Z28: =IF(COUNT(T28:V28)=0,"",SUM(W28:Y28)) | AA28: =IF(Z28="","",Z28*$AA$15) | AB28: =IF(COUNT(F28:J28,N28:P28,T28:V28)=0,"",SUM(M28,S28,AA28)) | AC28: =IF(AB28="","",IFERROR(INDEX(HELPER!$D$8:$D$48,IF(AB28>=HELPER!$B$8,1,MATCH(AB28,HELPER!$B$8:$B$48,-1)+1)),"")) | AD28: =IF(AC28="","",IFERROR(INDEX(HELPER!$G$8:$G$48,MATCH(AC28,HELPER!$F$8:$F$48,-1)),""))
B29: 12 | C29: =IF('INPUT DATA'!K22="","",'INPUT DATA'!K22) | K29: =IF(COUNT($F29:$J29)=0,"",SUM($F29:$J29)) | L29: =IF(COUNT(F29:J29)=0,"",IFERROR(K29/$K$15*$L$15,"")) | M29: =IF(L29="","",L29*$M$15) | Q29: =IF(COUNT(N29:P29)=0,"",SUM(N29:P29)) | R29: =IF(COUNT(N29:P29)=0,"",IFERROR(Q29/$Q$15*$R$15,"")) | S29: =IF(R29="","",R29*$S$15) | W29: =IF(T29="","",IFERROR(T29/$T$15*$W$15,"")) | X29: =IF(U29="","",IFERROR(U29/$U$15*$X$15,"")) | Y29: =IF(V29="","",IFERROR(V29/$V$15*$Y$15,"")) | Z29: =IF(COUNT(T29:V29)=0,"",SUM(W29:Y29)) | AA29: =IF(Z29="","",Z29*$AA$15) | AB29: =IF(COUNT(F29:J29,N29:P29,T29:V29)=0,"",SUM(M29,S29,AA29)) | AC29: =IF(AB29="","",IFERROR(INDEX(HELPER!$D$8:$D$48,IF(AB29>=HELPER!$B$8,1,MATCH(AB29,HELPER!$B$8:$B$48,-1)+1)),"")) | AD29: =IF(AC29="","",IFERROR(INDEX(HELPER!$G$8:$G$48,MATCH(AC29,HELPER!$F$8:$F$48,-1)),""))
... B58: 41 | C58: =IF('INPUT DATA'!K51="","",'INPUT DATA'!K51) | K58: =IF(COUNT($F58:$J58)=0,"",SUM($F58:$J58)) | L58: =IF(COUNT(F58:J58)=0,"",IFERROR(K58/$K$15*$L$15,"")) | M58: =IF(L58="","",L58*$M$15) | Q58: =IF(COUNT(N58:P58)=0,"",SUM(N58:P58)) | R58: =IF(COUNT(N58:P58)=0,"",IFERROR(Q58/$Q$15*$R$15,"")) | S58: =IF(R58="","",R58*$S$15) | W58: =IF(T58="","",IFERROR(T58/$T$15*$W$15,"")) | X58: =IF(U58="","",IFERROR(U58/$U$15*$X$15,"")) | Y58: =IF(V58="","",IFERROR(V58/$V$15*$Y$15,"")) | Z58: =IF(COUNT(T58:V58)=0,"",SUM(W58:Y58)) | AA58: =IF(Z58="","",Z58*$AA$15) | AB58: =IF(COUNT(F58:J58,N58:P58,T58:V58)=0,"",SUM(M58,S58,AA58)) | AC58: =IF(AB58="","",IFERROR(INDEX(HELPER!$D$8:$D$48,IF(AB58>=HELPER!$B$8,1,MATCH(AB58,HELPER!$B$8:$B$48,-1)+1)),"")) | AD58: =IF(AC58="","",IFERROR(INDEX(HELPER!$G$8:$G$48,MATCH(AC58,HELPER!$F$8:$F$48,-1)),""))
B59: 42 | C59: =IF('INPUT DATA'!K52="","",'INPUT DATA'!K52) | K59: =IF(COUNT($F59:$J59)=0,"",SUM($F59:$J59)) | L59: =IF(COUNT(F59:J59)=0,"",IFERROR(K59/$K$15*$L$15,"")) | M59: =IF(L59="","",L59*$M$15) | Q59: =IF(COUNT(N59:P59)=0,"",SUM(N59:P59)) | R59: =IF(COUNT(N59:P59)=0,"",IFERROR(Q59/$Q$15*$R$15,"")) | S59: =IF(R59="","",R59*$S$15) | W59: =IF(T59="","",IFERROR(T59/$T$15*$W$15,"")) | X59: =IF(U59="","",IFERROR(U59/$U$15*$X$15,"")) | Y59: =IF(V59="","",IFERROR(V59/$V$15*$Y$15,"")) | Z59: =IF(COUNT(T59:V59)=0,"",SUM(W59:Y59)) | AA59: =IF(Z59="","",Z59*$AA$15) | AB59: =IF(COUNT(F59:J59,N59:P59,T59:V59)=0,"",SUM(M59,S59,AA59)) | AC59: =IF(AB59="","",IFERROR(INDEX(HELPER!$D$8:$D$48,IFERROR(MATCH(AB59,HELPER!$B$8:$B$48,0),MATCH(AB59,HELPER!$B$8:$B$48,-1)+1)),"")) | AD59: =IF(AC59="","",IFERROR(INDEX(HELPER!$G$8:$G$48,MATCH(AC59,HELPER!$F$8:$F$48,-1)),""))
B60: 43 | C60: =IF('INPUT DATA'!K53="","",'INPUT DATA'!K53) | K60: =IF(COUNT($F60:$J60)=0,"",SUM($F60:$J60)) | L60: =IF(COUNT(F60:J60)=0,"",IFERROR(K60/$K$15*$L$15,"")) | M60: =IF(L60="","",L60*$M$15) | Q60: =IF(COUNT(N60:P60)=0,"",SUM(N60:P60)) | R60: =IF(COUNT(N60:P60)=0,"",IFERROR(Q60/$Q$15*$R$15,"")) | S60: =IF(R60="","",R60*$S$15) | W60: =IF(T60="","",IFERROR(T60/$T$15*$W$15,"")) | X60: =IF(U60="","",IFERROR(U60/$U$15*$X$15,"")) | Y60: =IF(V60="","",IFERROR(V60/$V$15*$Y$15,"")) | Z60: =IF(COUNT(T60:V60)=0,"",SUM(W60:Y60)) | AA60: =IF(Z60="","",Z60*$AA$15) | AB60: =IF(COUNT(F60:J60,N60:P60,T60:V60)=0,"",SUM(M60,S60,AA60)) | AC60: =IF(AB60="","",IFERROR(INDEX(HELPER!$D$8:$D$48,IFERROR(MATCH(AB60,HELPER!$B$8:$B$48,0),MATCH(AB60,HELPER!$B$8:$B$48,-1)+1)),"")) | AD60: =IF(AC60="","",IFERROR(INDEX(HELPER!$G$8:$G$48,MATCH(AC60,HELPER!$F$8:$F$48,-1)),""))
B61: 44 | C61: =IF('INPUT DATA'!K54="","",'INPUT DATA'!K54) | K61: =IF(COUNT($F61:$J61)=0,"",SUM($F61:$J61)) | L61: =IF(COUNT(F61:J61)=0,"",IFERROR(K61/$K$15*$L$15,"")) | M61: =IF(L61="","",L61*$M$15) | Q61: =IF(COUNT(N61:P61)=0,"",SUM(N61:P61)) | R61: =IF(COUNT(N61:P61)=0,"",IFERROR(Q61/$Q$15*$R$15,"")) | S61: =IF(R61="","",R61*$S$15) | W61: =IF(T61="","",IFERROR(T61/$T$15*$W$15,"")) | X61: =IF(U61="","",IFERROR(U61/$U$15*$X$15,"")) | Y61: =IF(V61="","",IFERROR(V61/$V$15*$Y$15,"")) | Z61: =IF(COUNT(T61:V61)=0,"",SUM(W61:Y61)) | AA61: =IF(Z61="","",Z61*$AA$15) | AB61: =IF(COUNT(F61:J61,N61:P61,T61:V61)=0,"",SUM(M61,S61,AA61)) | AC61: =IF(AB61="","",IFERROR(INDEX(HELPER!$D$8:$D$48,IFERROR(MATCH(AB61,HELPER!$B$8:$B$48,0),MATCH(AB61,HELPER!$B$8:$B$48,-1)+1)),"")) | AD61: =IF(AC61="","",IFERROR(INDEX(HELPER!$G$8:$G$48,MATCH(AC61,HELPER!$F$8:$F$48,-1)),""))
B62: 45 | C62: =IF('INPUT DATA'!K55="","",'INPUT DATA'!K55) | K62: =IF(COUNT($F62:$J62)=0,"",SUM($F62:$J62)) | L62: =IF(COUNT(F62:J62)=0,"",IFERROR(K62/$K$15*$L$15,"")) | M62: =IF(L62="","",L62*$M$15) | Q62: =IF(COUNT(N62:P62)=0,"",SUM(N62:P62)) | R62: =IF(COUNT(N62:P62)=0,"",IFERROR(Q62/$Q$15*$R$15,"")) | S62: =IF(R62="","",R62*$S$15) | W62: =IF(T62="","",IFERROR(T62/$T$15*$W$15,"")) | X62: =IF(U62="","",IFERROR(U62/$U$15*$X$15,"")) | Y62: =IF(V62="","",IFERROR(V62/$V$15*$Y$15,"")) | Z62: =IF(COUNT(T62:V62)=0,"",SUM(W62:Y62)) | AA62: =IF(Z62="","",Z62*$AA$15) | AB62: =IF(COUNT(F62:J62,N62:P62,T62:V62)=0,"",SUM(M62,S62,AA62)) | AC62: =IF(AB62="","",IFERROR(INDEX(HELPER!$D$8:$D$48,IFERROR(MATCH(AB62,HELPER!$B$8:$B$48,0),MATCH(AB62,HELPER!$B$8:$B$48,-1)+1)),"")) | AD62: =IF(AC62="","",IFERROR(INDEX(HELPER!$G$8:$G$48,MATCH(AC62,HELPER!$F$8:$F$48,-1)),""))
B63: 46 | C63: =IF('INPUT DATA'!K56="","",'INPUT DATA'!K56) | K63: =IF(COUNT($F63:$J63)=0,"",SUM($F63:$J63)) | L63: =IF(COUNT(F63:J63)=0,"",IFERROR(K63/$K$15*$L$15,"")) | M63: =IF(L63="","",L63*$M$15) | Q63: =IF(COUNT(N63:P63)=0,"",SUM(N63:P63)) | R63: =IF(COUNT(N63:P63)=0,"",IFERROR(Q63/$Q$15*$R$15,"")) | S63: =IF(R63="","",R63*$S$15) | W63: =IF(T63="","",IFERROR(T63/$T$15*$W$15,"")) | X63: =IF(U63="","",IFERROR(U63/$U$15*$X$15,"")) | Y63: =IF(V63="","",IFERROR(V63/$V$15*$Y$15,"")) | Z63: =IF(COUNT(T63:V63)=0,"",SUM(W63:Y63)) | AA63: =IF(Z63="","",Z63*$AA$15) | AB63: =IF(COUNT(F63:J63,N63:P63,T63:V63)=0,"",SUM(M63,S63,AA63)) | AC63: =IF(AB63="","",IFERROR(INDEX(HELPER!$D$8:$D$48,IFERROR(MATCH(AB63,HELPER!$B$8:$B$48,0),MATCH(AB63,HELPER!$B$8:$B$48,-1)+1)),"")) | AD63: =IF(AC63="","",IFERROR(INDEX(HELPER!$G$8:$G$48,MATCH(AC63,HELPER!$F$8:$F$48,-1)),""))
B64: 47 | C64: =IF('INPUT DATA'!K57="","",'INPUT DATA'!K57) | K64: =IF(COUNT($F64:$J64)=0,"",SUM($F64:$J64)) | L64: =IF(COUNT(F64:J64)=0,"",IFERROR(K64/$K$15*$L$15,"")) | M64: =IF(L64="","",L64*$M$15) | Q64: =IF(COUNT(N64:P64)=0,"",SUM(N64:P64)) | R64: =IF(COUNT(N64:P64)=0,"",IFERROR(Q64/$Q$15*$R$15,"")) | S64: =IF(R64="","",R64*$S$15) | W64: =IF(T64="","",IFERROR(T64/$T$15*$W$15,"")) | X64: =IF(U64="","",IFERROR(U64/$U$15*$X$15,"")) | Y64: =IF(V64="","",IFERROR(V64/$V$15*$Y$15,"")) | Z64: =IF(COUNT(T64:V64)=0,"",SUM(W64:Y64)) | AA64: =IF(Z64="","",Z64*$AA$15) | AB64: =IF(COUNT(F64:J64,N64:P64,T64:V64)=0,"",SUM(M64,S64,AA64)) | AC64: =IF(AB64="","",IFERROR(INDEX(HELPER!$D$8:$D$48,IFERROR(MATCH(AB64,HELPER!$B$8:$B$48,0),MATCH(AB64,HELPER!$B$8:$B$48,-1)+1)),"")) | AD64: =IF(AC64="","",IFERROR(INDEX(HELPER!$G$8:$G$48,MATCH(AC64,HELPER!$F$8:$F$48,-1)),""))
B65: 48 | C65: =IF('INPUT DATA'!K58="","",'INPUT DATA'!K58) | K65: =IF(COUNT($F65:$J65)=0,"",SUM($F65:$J65)) | L65: =IF(COUNT(F65:J65)=0,"",IFERROR(K65/$K$15*$L$15,"")) | M65: =IF(L65="","",L65*$M$15) | Q65: =IF(COUNT(N65:P65)=0,"",SUM(N65:P65)) | R65: =IF(COUNT(N65:P65)=0,"",IFERROR(Q65/$Q$15*$R$15,"")) | S65: =IF(R65="","",R65*$S$15) | W65: =IF(T65="","",IFERROR(T65/$T$15*$W$15,"")) | X65: =IF(U65="","",IFERROR(U65/$U$15*$X$15,"")) | Y65: =IF(V65="","",IFERROR(V65/$V$15*$Y$15,"")) | Z65: =IF(COUNT(T65:V65)=0,"",SUM(W65:Y65)) | AA65: =IF(Z65="","",Z65*$AA$15) | AB65: =IF(COUNT(F65:J65,N65:P65,T65:V65)=0,"",SUM(M65,S65,AA65)) | AC65: =IF(AB65="","",IFERROR(INDEX(HELPER!$D$8:$D$48,IFERROR(MATCH(AB65,HELPER!$B$8:$B$48,0),MATCH(AB65,HELPER!$B$8:$B$48,-1)+1)),"")) | AD65: =IF(AC65="","",IFERROR(INDEX(HELPER!$G$8:$G$48,MATCH(AC65,HELPER!$F$8:$F$48,-1)),""))
B66: 49 | C66: =IF('INPUT DATA'!K59="","",'INPUT DATA'!K59) | K66: =IF(COUNT($F66:$J66)=0,"",SUM($F66:$J66)) | L66: =IF(COUNT(F66:J66)=0,"",IFERROR(K66/$K$15*$L$15,"")) | M66: =IF(L66="","",L66*$M$15) | Q66: =IF(COUNT(N66:P66)=0,"",SUM(N66:P66)) | R66: =IF(COUNT(N66:P66)=0,"",IFERROR(Q66/$Q$15*$R$15,"")) | S66: =IF(R66="","",R66*$S$15) | W66: =IF(T66="","",IFERROR(T66/$T$15*$W$15,"")) | X66: =IF(U66="","",IFERROR(U66/$U$15*$X$15,"")) | Y66: =IF(V66="","",IFERROR(V66/$V$15*$Y$15,"")) | Z66: =IF(COUNT(T66:V66)=0,"",SUM(W66:Y66)) | AA66: =IF(Z66="","",Z66*$AA$15) | AB66: =IF(COUNT(F66:J66,N66:P66,T66:V66)=0,"",SUM(M66,S66,AA66)) | AC66: =IF(AB66="","",IFERROR(INDEX(HELPER!$D$8:$D$48,IFERROR(MATCH(AB66,HELPER!$B$8:$B$48,0),MATCH(AB66,HELPER!$B$8:$B$48,-1)+1)),"")) | AD66: =IF(AC66="","",IFERROR(INDEX(HELPER!$G$8:$G$48,MATCH(AC66,HELPER!$F$8:$F$48,-1)),""))
B67: 50 | C67: =IF('INPUT DATA'!K60="","",'INPUT DATA'!K60) | K67: =IF(COUNT($F67:$J67)=0,"",SUM($F67:$J67)) | L67: =IF(COUNT(F67:J67)=0,"",IFERROR(K67/$K$15*$L$15,"")) | M67: =IF(L67="","",L67*$M$15) | Q67: =IF(COUNT(N67:P67)=0,"",SUM(N67:P67)) | R67: =IF(COUNT(N67:P67)=0,"",IFERROR(Q67/$Q$15*$R$15,"")) | S67: =IF(R67="","",R67*$S$15) | W67: =IF(T67="","",IFERROR(T67/$T$15*$W$15,"")) | X67: =IF(U67="","",IFERROR(U67/$U$15*$X$15,"")) | Y67: =IF(V67="","",IFERROR(V67/$V$15*$Y$15,"")) | Z67: =IF(COUNT(T67:V67)=0,"",SUM(W67:Y67)) | AA67: =IF(Z67="","",Z67*$AA$15) | AB67: =IF(COUNT(F67:J67,N67:P67,T67:V67)=0,"",SUM(M67,S67,AA67)) | AC67: =IF(AB67="","",IFERROR(INDEX(HELPER!$D$8:$D$48,IFERROR(MATCH(AB67,HELPER!$B$8:$B$48,0),MATCH(AB67,HELPER!$B$8:$B$48,-1)+1)),"")) | AD67: =IF(AC67="","",IFERROR(INDEX(HELPER!$G$8:$G$48,MATCH(AC67,HELPER!$F$8:$F$48,-1)),""))
B68: FEMALE
B69: 1 | C69: =IF('INPUT DATA'!N11="","",'INPUT DATA'!N11) | K69: =IF(COUNT($F69:$J69)=0,"",SUM($F69:$J69)) | L69: =IF(COUNT(F69:J69)=0,"",IFERROR(K69/$K$15*$L$15,"")) | M69: =IF(L69="","",L69*$M$15) | Q69: =IF(COUNT(N69:P69)=0,"",SUM(N69:P69)) | R69: =IF(COUNT(N69:P69)=0,"",IFERROR(Q69/$Q$15*$R$15,"")) | S69: =IF(R69="","",R69*$S$15) | W69: =IF(T69="","",IFERROR(T69/$T$15*$W$15,"")) | X69: =IF(U69="","",IFERROR(U69/$U$15*$X$15,"")) | Y69: =IF(V69="","",IFERROR(V69/$V$15*$Y$15,"")) | Z69: =IF(COUNT(T69:V69)=0,"",SUM(W69:Y69)) | AA69: =IF(Z69="","",Z69*$AA$15) | AB69: =IF(COUNT(F69:J69,N69:P69,T69:V69)=0,"",SUM(M69,S69,AA69)) | AC69: =IF(AB69="","",IFERROR(INDEX(HELPER!$D$8:$D$48,IFERROR(MATCH(AB69,HELPER!$B$8:$B$48,0),MATCH(AB69,HELPER!$B$8:$B$48,-1)+1)),"")) | AD69: =IF(AC69="","",IFERROR(INDEX(HELPER!$G$8:$G$48,MATCH(AC69,HELPER!$F$8:$F$48,-1)),""))
B70: 2 | C70: =IF('INPUT DATA'!N12="","",'INPUT DATA'!N12) | K70: =IF(COUNT($F70:$J70)=0,"",SUM($F70:$J70)) | L70: =IF(COUNT(F70:J70)=0,"",IFERROR(K70/$K$15*$L$15,"")) | M70: =IF(L70="","",L70*$M$15) | Q70: =IF(COUNT(N70:P70)=0,"",SUM(N70:P70)) | R70: =IF(COUNT(N70:P70)=0,"",IFERROR(Q70/$Q$15*$R$15,"")) | S70: =IF(R70="","",R70*$S$15) | W70: =IF(T70="","",IFERROR(T70/$T$15*$W$15,"")) | X70: =IF(U70="","",IFERROR(U70/$U$15*$X$15,"")) | Y70: =IF(V70="","",IFERROR(V70/$V$15*$Y$15,"")) | Z70: =IF(COUNT(T70:V70)=0,"",SUM(W70:Y70)) | AA70: =IF(Z70="","",Z70*$AA$15) | AB70: =IF(COUNT(F70:J70,N70:P70,T70:V70)=0,"",SUM(M70,S70,AA70)) | AC70: =IF(AB70="","",IFERROR(INDEX(HELPER!$D$8:$D$48,IFERROR(MATCH(AB70,HELPER!$B$8:$B$48,0),MATCH(AB70,HELPER!$B$8:$B$48,-1)+1)),"")) | AD70: =IF(AC70="","",IFERROR(INDEX(HELPER!$G$8:$G$48,MATCH(AC70,HELPER!$F$8:$F$48,-1)),""))
B71: 3 | C71: =IF('INPUT DATA'!N13="","",'INPUT DATA'!N13) | K71: =IF(COUNT($F71:$J71)=0,"",SUM($F71:$J71)) | L71: =IF(COUNT(F71:J71)=0,"",IFERROR(K71/$K$15*$L$15,"")) | M71: =IF(L71="","",L71*$M$15) | Q71: =IF(COUNT(N71:P71)=0,"",SUM(N71:P71)) | R71: =IF(COUNT(N71:P71)=0,"",IFERROR(Q71/$Q$15*$R$15,"")) | S71: =IF(R71="","",R71*$S$15) | W71: =IF(T71="","",IFERROR(T71/$T$15*$W$15,"")) | X71: =IF(U71="","",IFERROR(U71/$U$15*$X$15,"")) | Y71: =IF(V71="","",IFERROR(V71/$V$15*$Y$15,"")) | Z71: =IF(COUNT(T71:V71)=0,"",SUM(W71:Y71)) | AA71: =IF(Z71="","",Z71*$AA$15) | AB71: =IF(COUNT(F71:J71,N71:P71,T71:V71)=0,"",SUM(M71,S71,AA71)) | AC71: =IF(AB71="","",IFERROR(INDEX(HELPER!$D$8:$D$48,IFERROR(MATCH(AB71,HELPER!$B$8:$B$48,0),MATCH(AB71,HELPER!$B$8:$B$48,-1)+1)),"")) | AD71: =IF(AC71="","",IFERROR(INDEX(HELPER!$G$8:$G$48,MATCH(AC71,HELPER!$F$8:$F$48,-1)),""))
B72: 4 | C72: =IF('INPUT DATA'!N14="","",'INPUT DATA'!N14) | K72: =IF(COUNT($F72:$J72)=0,"",SUM($F72:$J72)) | L72: =IF(COUNT(F72:J72)=0,"",IFERROR(K72/$K$15*$L$15,"")) | M72: =IF(L72="","",L72*$M$15) | Q72: =IF(COUNT(N72:P72)=0,"",SUM(N72:P72)) | R72: =IF(COUNT(N72:P72)=0,"",IFERROR(Q72/$Q$15*$R$15,"")) | S72: =IF(R72="","",R72*$S$15) | W72: =IF(T72="","",IFERROR(T72/$T$15*$W$15,"")) | X72: =IF(U72="","",IFERROR(U72/$U$15*$X$15,"")) | Y72: =IF(V72="","",IFERROR(V72/$V$15*$Y$15,"")) | Z72: =IF(COUNT(T72:V72)=0,"",SUM(W72:Y72)) | AA72: =IF(Z72="","",Z72*$AA$15) | AB72: =IF(COUNT(F72:J72,N72:P72,T72:V72)=0,"",SUM(M72,S72,AA72)) | AC72: =IF(AB72="","",IFERROR(INDEX(HELPER!$D$8:$D$48,IFERROR(MATCH(AB72,HELPER!$B$8:$B$48,0),MATCH(AB72,HELPER!$B$8:$B$48,-1)+1)),"")) | AD72: =IF(AC72="","",IFERROR(INDEX(HELPER!$G$8:$G$48,MATCH(AC72,HELPER!$F$8:$F$48,-1)),""))
B73: 5 | C73: =IF('INPUT DATA'!N15="","",'INPUT DATA'!N15) | K73: =IF(COUNT($F73:$J73)=0,"",SUM($F73:$J73)) | L73: =IF(COUNT(F73:J73)=0,"",IFERROR(K73/$K$15*$L$15,"")) | M73: =IF(L73="","",L73*$M$15) | Q73: =IF(COUNT(N73:P73)=0,"",SUM(N73:P73)) | R73: =IF(COUNT(N73:P73)=0,"",IFERROR(Q73/$Q$15*$R$15,"")) | S73: =IF(R73="","",R73*$S$15) | W73: =IF(T73="","",IFERROR(T73/$T$15*$W$15,"")) | X73: =IF(U73="","",IFERROR(U73/$U$15*$X$15,"")) | Y73: =IF(V73="","",IFERROR(V73/$V$15*$Y$15,"")) | Z73: =IF(COUNT(T73:V73)=0,"",SUM(W73:Y73)) | AA73: =IF(Z73="","",Z73*$AA$15) | AB73: =IF(COUNT(F73:J73,N73:P73,T73:V73)=0,"",SUM(M73,S73,AA73)) | AC73: =IF(AB73="","",IFERROR(INDEX(HELPER!$D$8:$D$48,IFERROR(MATCH(AB73,HELPER!$B$8:$B$48,0),MATCH(AB73,HELPER!$B$8:$B$48,-1)+1)),"")) | AD73: =IF(AC73="","",IFERROR(INDEX(HELPER!$G$8:$G$48,MATCH(AC73,HELPER!$F$8:$F$48,-1)),""))
B74: 6 | C74: =IF('INPUT DATA'!N16="","",'INPUT DATA'!N16) | K74: =IF(COUNT($F74:$J74)=0,"",SUM($F74:$J74)) | L74: =IF(COUNT(F74:J74)=0,"",IFERROR(K74/$K$15*$L$15,"")) | M74: =IF(L74="","",L74*$M$15) | Q74: =IF(COUNT(N74:P74)=0,"",SUM(N74:P74)) | R74: =IF(COUNT(N74:P74)=0,"",IFERROR(Q74/$Q$15*$R$15,"")) | S74: =IF(R74="","",R74*$S$15) | W74: =IF(T74="","",IFERROR(T74/$T$15*$W$15,"")) | X74: =IF(U74="","",IFERROR(U74/$U$15*$X$15,"")) | Y74: =IF(V74="","",IFERROR(V74/$V$15*$Y$15,"")) | Z74: =IF(COUNT(T74:V74)=0,"",SUM(W74:Y74)) | AA74: =IF(Z74="","",Z74*$AA$15) | AB74: =IF(COUNT(F74:J74,N74:P74,T74:V74)=0,"",SUM(M74,S74,AA74)) | AC74: =IF(AB74="","",IFERROR(INDEX(HELPER!$D$8:$D$48,IFERROR(MATCH(AB74,HELPER!$B$8:$B$48,0),MATCH(AB74,HELPER!$B$8:$B$48,-1)+1)),"")) | AD74: =IF(AC74="","",IFERROR(INDEX(HELPER!$G$8:$G$48,MATCH(AC74,HELPER!$F$8:$F$48,-1)),""))
B75: 7 | C75: =IF('INPUT DATA'!N17="","",'INPUT DATA'!N17) | K75: =IF(COUNT($F75:$J75)=0,"",SUM($F75:$J75)) | L75: =IF(COUNT(F75:J75)=0,"",IFERROR(K75/$K$15*$L$15,"")) | M75: =IF(L75="","",L75*$M$15) | Q75: =IF(COUNT(N75:P75)=0,"",SUM(N75:P75)) | R75: =IF(COUNT(N75:P75)=0,"",IFERROR(Q75/$Q$15*$R$15,"")) | S75: =IF(R75="","",R75*$S$15) | W75: =IF(T75="","",IFERROR(T75/$T$15*$W$15,"")) | X75: =IF(U75="","",IFERROR(U75/$U$15*$X$15,"")) | Y75: =IF(V75="","",IFERROR(V75/$V$15*$Y$15,"")) | Z75: =IF(COUNT(T75:V75)=0,"",SUM(W75:Y75)) | AA75: =IF(Z75="","",Z75*$AA$15) | AB75: =IF(COUNT(F75:J75,N75:P75,T75:V75)=0,"",SUM(M75,S75,AA75)) | AC75: =IF(AB75="","",IFERROR(INDEX(HELPER!$D$8:$D$48,IFERROR(MATCH(AB75,HELPER!$B$8:$B$48,0),MATCH(AB75,HELPER!$B$8:$B$48,-1)+1)),"")) | AD75: =IF(AC75="","",IFERROR(INDEX(HELPER!$G$8:$G$48,MATCH(AC75,HELPER!$F$8:$F$48,-1)),""))
...

Sheet TERM 3
B2: CLASS RECORD
E5: REGION | F5: =IF('INPUT DATA'!E10="","",'INPUT DATA'!E10) | Q5: DIVISION | R5: =IF('INPUT DATA'!E11="","",'INPUT DATA'!E11) | Y5: SCHOOL ID | Z5: =IF('INPUT DATA'!E13="","",'INPUT DATA'!E13)
E7: SCHOOL NAME | F7: =IF('INPUT DATA'!E14="","",'INPUT DATA'!E14) | Y7: SCHOOL YEAR | Z7: =IF('INPUT DATA'!E15="","",'INPUT DATA'!E15)
B10: THIRD TERM | F10: GRADE LEVEL | J10: =IF('INPUT DATA'!E25="","",'INPUT DATA'!E25) | N10: TEACHER | Q10: =IF('INPUT DATA'!E23="","",'INPUT DATA'!E23) | Y10: SUBJECT | AA10: =IF('INPUT DATA'!E24="","",'INPUT DATA'!E24)
F11: SECTION | J11: =IF('INPUT DATA'!E26="","",'INPUT DATA'!E26)
F12: WRITTEN / ORAL WORKS (WWs) | N12: PRODUCT / PERFORMANCE TASKS (PTs) | T12: EXAMINATIONS (EXs) | AB12: Initial Grade | AC12: Term Grade | AD12: Descriptor
F14: 1 | G14: 2 | H14: 3 | I14: 4 | J14: 5 | K14: Total | L14: PS | M14: WS | N14: 1 | O14: 2 | P14: 3 | Q14: Total | R14: PS | S14: WS | T14: ST1 | U14: ST2 | V14: TE | W14: WS ST1 | X14: WS ST2 | Y14: WS TE | Z14: PS | AA14: WS
B15: HIGHEST POSSIBLE SCORE | K15: =IF(COUNT(F15:J15)=0,"",SUM(F15:J15)) | L15: 100 | M15: 0.2 | Q15: =IF(COUNT(N15:P15)=0,"",SUM(N15:P15)) | R15: 100 | S15: 0.6 | W15: 30 | X15: 30 | Y15: 40 | Z15: 100 | AA15: 0.2
B16: LEARNERS' NAMES
B17: MALE
B18: 1 | C18: =IF('INPUT DATA'!K11="","",'INPUT DATA'!K11) | K18: =IF(COUNT($F18:$J18)=0,"",SUM($F18:$J18)) | L18: =IF(COUNT(F18:J18)=0,"",IFERROR(K18/$K$15*$L$15,"")) | M18: =IF(L18="","",L18*$M$15) | Q18: =IF(COUNT(N18:P18)=0,"",SUM(N18:P18)) | R18: =IF(COUNT(N18:P18)=0,"",IFERROR(Q18/$Q$15*$R$15,"")) | S18: =IF(R18="","",R18*$S$15) | W18: =IF(T18="","",IFERROR(T18/$T$15*$W$15,"")) | X18: =IF(U18="","",IFERROR(U18/$U$15*$X$15,"")) | Y18: =IF(V18="","",IFERROR(V18/$V$15*$Y$15,"")) | Z18: =IF(COUNT(T18:V18)=0,"",SUM(W18:Y18)) | AA18: =IF(Z18="","",Z18*$AA$15) | AB18: =IF(COUNT(F18:J18,N18:P18,T18:V18)=0,"",SUM(M18,S18,AA18)) | AC18: =IF(AB18="","",IFERROR(INDEX(HELPER!$D$8:$D$48,IF(AB18>=HELPER!$B$8,1,MATCH(AB18,HELPER!$B$8:$B$48,-1)+1)),"")) | AD18: =IF(AC18="","",IFERROR(INDEX(HELPER!$G$8:$G$48,MATCH(AC18,HELPER!$F$8:$F$48,-1)),""))
B19: 2 | C19: =IF('INPUT DATA'!K12="","",'INPUT DATA'!K12) | K19: =IF(COUNT($F19:$J19)=0,"",SUM($F19:$J19)) | L19: =IF(COUNT(F19:J19)=0,"",IFERROR(K19/$K$15*$L$15,"")) | M19: =IF(L19="","",L19*$M$15) | Q19: =IF(COUNT(N19:P19)=0,"",SUM(N19:P19)) | R19: =IF(COUNT(N19:P19)=0,"",IFERROR(Q19/$Q$15*$R$15,"")) | S19: =IF(R19="","",R19*$S$15) | W19: =IF(T19="","",IFERROR(T19/$T$15*$W$15,"")) | X19: =IF(U19="","",IFERROR(U19/$U$15*$X$15,"")) | Y19: =IF(V19="","",IFERROR(V19/$V$15*$Y$15,"")) | Z19: =IF(COUNT(T19:V19)=0,"",SUM(W19:Y19)) | AA19: =IF(Z19="","",Z19*$AA$15) | AB19: =IF(COUNT(F19:J19,N19:P19,T19:V19)=0,"",SUM(M19,S19,AA19)) | AC19: =IF(AB19="","",IFERROR(INDEX(HELPER!$D$8:$D$48,IF(AB19>=HELPER!$B$8,1,MATCH(AB19,HELPER!$B$8:$B$48,-1)+1)),"")) | AD19: =IF(AC19="","",IFERROR(INDEX(HELPER!$G$8:$G$48,MATCH(AC19,HELPER!$F$8:$F$48,-1)),""))
B20: 3 | C20: =IF('INPUT DATA'!K13="","",'INPUT DATA'!K13) | K20: =IF(COUNT($F20:$J20)=0,"",SUM($F20:$J20)) | L20: =IF(COUNT(F20:J20)=0,"",IFERROR(K20/$K$15*$L$15,"")) | M20: =IF(L20="","",L20*$M$15) | Q20: =IF(COUNT(N20:P20)=0,"",SUM(N20:P20)) | R20: =IF(COUNT(N20:P20)=0,"",IFERROR(Q20/$Q$15*$R$15,"")) | S20: =IF(R20="","",R20*$S$15) | W20: =IF(T20="","",IFERROR(T20/$T$15*$W$15,"")) | X20: =IF(U20="","",IFERROR(U20/$U$15*$X$15,"")) | Y20: =IF(V20="","",IFERROR(V20/$V$15*$Y$15,"")) | Z20: =IF(COUNT(T20:V20)=0,"",SUM(W20:Y20)) | AA20: =IF(Z20="","",Z20*$AA$15) | AB20: =IF(COUNT(F20:J20,N20:P20,T20:V20)=0,"",SUM(M20,S20,AA20)) | AC20: =IF(AB20="","",IFERROR(INDEX(HELPER!$D$8:$D$48,IF(AB20>=HELPER!$B$8,1,MATCH(AB20,HELPER!$B$8:$B$48,-1)+1)),"")) | AD20: =IF(AC20="","",IFERROR(INDEX(HELPER!$G$8:$G$48,MATCH(AC20,HELPER!$F$8:$F$48,-1)),""))
B21: 4 | C21: =IF('INPUT DATA'!K14="","",'INPUT DATA'!K14) | K21: =IF(COUNT($F21:$J21)=0,"",SUM($F21:$J21)) | L21: =IF(COUNT(F21:J21)=0,"",IFERROR(K21/$K$15*$L$15,"")) | M21: =IF(L21="","",L21*$M$15) | Q21: =IF(COUNT(N21:P21)=0,"",SUM(N21:P21)) | R21: =IF(COUNT(N21:P21)=0,"",IFERROR(Q21/$Q$15*$R$15,"")) | S21: =IF(R21="","",R21*$S$15) | W21: =IF(T21="","",IFERROR(T21/$T$15*$W$15,"")) | X21: =IF(U21="","",IFERROR(U21/$U$15*$X$15,"")) | Y21: =IF(V21="","",IFERROR(V21/$V$15*$Y$15,"")) | Z21: =IF(COUNT(T21:V21)=0,"",SUM(W21:Y21)) | AA21: =IF(Z21="","",Z21*$AA$15) | AB21: =IF(COUNT(F21:J21,N21:P21,T21:V21)=0,"",SUM(M21,S21,AA21)) | AC21: =IF(AB21="","",IFERROR(INDEX(HELPER!$D$8:$D$48,IF(AB21>=HELPER!$B$8,1,MATCH(AB21,HELPER!$B$8:$B$48,-1)+1)),"")) | AD21: =IF(AC21="","",IFERROR(INDEX(HELPER!$G$8:$G$48,MATCH(AC21,HELPER!$F$8:$F$48,-1)),""))
B22: 5 | C22: =IF('INPUT DATA'!K15="","",'INPUT DATA'!K15) | K22: =IF(COUNT($F22:$J22)=0,"",SUM($F22:$J22)) | L22: =IF(COUNT(F22:J22)=0,"",IFERROR(K22/$K$15*$L$15,"")) | M22: =IF(L22="","",L22*$M$15) | Q22: =IF(COUNT(N22:P22)=0,"",SUM(N22:P22)) | R22: =IF(COUNT(N22:P22)=0,"",IFERROR(Q22/$Q$15*$R$15,"")) | S22: =IF(R22="","",R22*$S$15) | W22: =IF(T22="","",IFERROR(T22/$T$15*$W$15,"")) | X22: =IF(U22="","",IFERROR(U22/$U$15*$X$15,"")) | Y22: =IF(V22="","",IFERROR(V22/$V$15*$Y$15,"")) | Z22: =IF(COUNT(T22:V22)=0,"",SUM(W22:Y22)) | AA22: =IF(Z22="","",Z22*$AA$15) | AB22: =IF(COUNT(F22:J22,N22:P22,T22:V22)=0,"",SUM(M22,S22,AA22)) | AC22: =IF(AB22="","",IFERROR(INDEX(HELPER!$D$8:$D$48,IF(AB22>=HELPER!$B$8,1,MATCH(AB22,HELPER!$B$8:$B$48,-1)+1)),"")) | AD22: =IF(AC22="","",IFERROR(INDEX(HELPER!$G$8:$G$48,MATCH(AC22,HELPER!$F$8:$F$48,-1)),""))
